Workbook

Sheet 총괄표
B2: (주)케이씨에스 풋팅 검증 워크북
B3: 케이씨에스_FY2025_감사보고서.xml
B4: 검증 대상: 재무상태표, 손익계산서, 자본변동표, 현금흐름표 / 주석 34개
B6: 시트 | C6: 제 목 | D6: 링크 | E6: 푸팅 오류 | F6: 산식 오류 | G6: 크로스 오류 | H6: 조서 차이 | I6: 전기 차이 | J6: 구조 미인식 | K6: 조서 미매칭
B7: BS | C7: 재무상태표 | D7: =HYPERLINK("#'BS'!A1","바로가기") | E7: =SUMPRODUCT(--ISNUMBER('BS'!B46:B49))+SUMPRODUCT(--ISNUMBER('BS'!C46:C49)) | F7: =SUMPRODUCT(--ISNUMBER('BS'!B52:B55))+SUMPRODUCT(--ISNUMBER('BS'!C52:C55)) | G7: 0 | H7: 0 | I7: 0 | J7: 0 | K7: 0
B8: PL | C8: 손익계산서 | D8: =HYPERLINK("#'PL'!A1","바로가기") | E8: =SUMPRODUCT(--ISNUMBER('PL'!B29:B29))+SUMPRODUCT(--ISNUMBER('PL'!C29:C29)) | F8: =SUMPRODUCT(--ISNUMBER('PL'!B32:B37))+SUMPRODUCT(--ISNUMBER('PL'!C32:C37)) | G8: 0 | H8: 0 | I8: 0 | J8: 0 | K8: 0
B9: CE | C9: 자본변동표 | D9: =HYPERLINK("#'CE'!A1","바로가기") | E9: =SUMPRODUCT(--ISNUMBER('CE'!B32:B34))+SUMPRODUCT(--ISNUMBER('CE'!C32:C34))+SUMPRODUCT(--ISNUMBER('CE'!D32:D34))+SUMPRODUCT(--ISNUMBER('CE'!E32:E34))+SUMPRODUCT(--ISNUMBER('CE'!F32:F34))+SUMPRODUCT(--ISNUMBER('CE'!G32:G34))+SUMPRODUCT(--ISNUMBER('CE'!H6:H6))+SUMPRODUCT(--ISNUMBER('CE'!H8:H8))+SUMPRODUCT(--ISNUMBER('CE'!H10:H12))+SUMPRODUCT(--ISNUMBER('CE'!H15:H18))+SUMPRODUCT(--ISNUMBER('CE'!H20:H20))+SUMPRODUCT(--ISNUMBER('CE'!H22:H24))+SUMPRODUCT(--ISNUMBER('CE'!H27:H29)) | F9: 0 | G9: =SUMPRODUCT(--ISNUMBER('CE'!B37:B39)) | H9: 0 | I9: 0 | J9: 0 | K9: 0
B10: CF | C10: 현금흐름표 | D10: =HYPERLINK("#'CF'!A1","바로가기") | E10: =SUMPRODUCT(--ISNUMBER('CF'!B34:B36))+SUMPRODUCT(--ISNUMBER('CF'!C34:C36)) | F10: =SUMPRODUCT(--ISNUMBER('CF'!B39:B40))+SUMPRODUCT(--ISNUMBER('CF'!C39:C40)) | G10: 0 | H10: 0 | I10: 0 | J10: 0 | K10: 0
B11: 1 | C11: 1. 회사의 개요 | D11: =HYPERLINK("#'1'!A1","바로가기") | E11: =SUMPRODUCT(--ISNUMBER('1'!B10:B10))+SUMPRODUCT(--ISNUMBER('1'!D10:D10)) | F11: 0 | G11: 0 | H11: 0 | I11: 0 | J11: 0 | K11: 0
B12: 2 | C12: 2. 중요한 회계정책 | D12: =HYPERLINK("#'2'!A1","바로가기") | E12: 0 | F12: 0 | G12: 0 | H12: 0 | I12: 0 | J12: 0 | K12: 0
B13: 3 | C13: 3. 중요한 회계추정 및 가정 | D13: =HYPERLINK("#'3'!A1","바로가기") | E13: 0 | F13: 0 | G13: 0 | H13: 0 | I13: 0 | J13: 0 | K13: 0
B14: 4 | C14: 4. 재무위험관리 | D14: =HYPERLINK("#'4'!A1","바로가기") | E14: =SUMPRODUCT(--ISNUMBER('4'!B60:B60))+SUMPRODUCT(--ISNUMBER('4'!B70:B70))+SUMPRODUCT(--ISNUMBER('4'!B83:B83))+SUMPRODUCT(--ISNUMBER('4'!B93:B93))+SUMPRODUCT(--ISNUMBER('4'!C51:C51))+SUMPRODUCT(--ISNUMBER('4'!C60:C60))+SUMPRODUCT(--ISNUMBER('4'!C70:C70))+SUMPRODUCT(--ISNUMBER('4'!C83:C83))+SUMPRODUCT(--ISNUMBER('4'!C93:C93))+SUMPRODUCT(--ISNUMBER('4'!D51:D51))+SUMPRODUCT(--ISNUMBER('4'!D60:D60))+SUMPRODUCT(--ISNUMBER('4'!D70:D70))+SUMPRODUCT(--ISNUMBER('4'!D83:D83))+SUMPRODUCT(--ISNUMBER('4'!D93:D93))+SUMPRODUCT(--ISNUMBER('4'!E60:E60))+SUMPRODUCT(--ISNUMBER('4'!E70:E70))+SUMPRODUCT(--ISNUMBER('4'!E83:E83))+SUMPRODUCT(--ISNUMBER('4'!E93:E93))+SUMPRODUCT(--ISNUMBER('4'!F51:F51))+SUMPRODUCT(--ISNUMBER('4'!F93:F93))+SUMPRODUCT(--ISNUMBER('4'!G51:G51)) | F14: 0 | G14: =SUMPRODUCT(--ISNUMBER('4'!B108:B109)) | H14: 0 | I14: 0 | J14: 0 | K14: 0
B15: 5 | C15: 5. 금융상품 공정가치 | D15: =HYPERLINK("#'5'!A1","바로가기") | E15: =SUMPRODUCT(--ISNUMBER('5'!B34:B34))+SUMPRODUCT(--ISNUMBER('5'!C34:C34)) | F15: 0 | G15: 0 | H15: 0 | I15: 0 | J15: 0 | K15: 0
B16: 6 | C16: 6. 범주별 금융상품 | D16: =HYPERLINK("#'6'!A1","바로가기") | E16: =SUMPRODUCT(--ISNUMBER('6'!B13:B13))+SUMPRODUCT(--ISNUMBER('6'!B24:B24))+SUMPRODUCT(--ISNUMBER('6'!B45:B45))+SUMPRODUCT(--ISNUMBER('6'!C13:C13))+SUMPRODUCT(--ISNUMBER('6'!C24:C24))+SUMPRODUCT(--ISNUMBER('6'!C45:C45))+SUMPRODUCT(--ISNUMBER('6'!D13:D13))+SUMPRODUCT(--ISNUMBER('6'!D24:D24))+SUMPRODUCT(--ISNUMBER('6'!E13:E13))+SUMPRODUCT(--ISNUMBER('6'!E24:E24)) | F16: 0 | G16: 0 | H16: 0 | I16: 0 | J16: 0 | K16: 0
B17: 7 | C17: 7. 영업부문 | D17: =HYPERLINK("#'7'!A1","바로가기") | E17: 0 | F17: 0 | G17: 0 | H17: 0 | I17: 0 | J17: 0 | K17: 0
B18: 8 | C18: 8. 현금및현금성자산 | D18: =HYPERLINK("#'8'!A1","바로가기") | E18: =SUMPRODUCT(--ISNUMBER('8'!B9:B9))+SUMPRODUCT(--ISNUMBER('8'!C9:C9)) | F18: 0 | G18: =SUMPRODUCT(--ISNUMBER('8'!B13:B13)) | H18: 0 | I18: 0 | J18: 0 | K18: 0
B19: 9 | C19: 9. 매출채권, 계약자산 및 기타 상각후원가 측정 금융자산 | D19: =HYPERLINK("#'9'!A1","바로가기") | E19: =SUMPRODUCT(--ISNUMBER('9'!B21:B22))+SUMPRODUCT(--ISNUMBER('9'!C21:C22))+SUMPRODUCT(--ISNUMBER('9'!D21:D22))+SUMPRODUCT(--ISNUMBER('9'!E21:E22))+SUMPRODUCT(--ISNUMBER('9'!F21:F22))+SUMPRODUCT(--ISNUMBER('9'!G21:G22)) | F19: 0 | G19: =SUMPRODUCT(--ISNUMBER('9'!B28:B29)) | H19: 0 | I19: 0 | J19: 0 | K19: 0
B20: 10 | C20: 10. 기타자산 | D20: =HYPERLINK("#'10'!A1","바로가기") | E20: =SUMPRODUCT(--ISNUMBER('10'!B10:B10))+SUMPRODUCT(--ISNUMBER('10'!C10:C10))+SUMPRODUCT(--ISNUMBER('10'!D10:D10))+SUMPRODUCT(--ISNUMBER('10'!E10:E10)) | F20: 0 | G20: =SUMPRODUCT(--ISNUMBER('10'!B14:B15)) | H20: 0 | I20: 0 | J20: 0 | K20: 0
B21: 11 | C21: 11. 재고자산 | D21: =HYPERLINK("#'11'!A1","바로가기") | E21: 0 | F21: 0 | G21: =SUMPRODUCT(--ISNUMBER('11'!B12:B12)) | H21: 0 | I21: 0 | J21: 0 | K21: 0
B22: 12 | C22: 12. 공정가치 측정 금융자산 | D22: =HYPERLINK("#'12'!A1","바로가기") | E22: =SUMPRODUCT(--ISNUMBER('12'!B21:B21))+SUMPRODUCT(--ISNUMBER('12'!B31:B31))+SUMPRODUCT(--ISNUMBER('12'!B39:B39))+SUMPRODUCT(--ISNUMBER('12'!C10:C10))+SUMPRODUCT(--ISNUMBER('12'!C21:C21))+SUMPRODUCT(--ISNUMBER('12'!C31:C31))+SUMPRODUCT(--ISNUMBER('12'!C39:C39))+SUMPRODUCT(--ISNUMBER('12'!D10:D10))+SUMPRODUCT(--ISNUMBER('12'!E10:E10))+SUMPRODUCT(--ISNUMBER('12'!F10:F10)) | F22: 0 | G22: 0 | H22: 0 | I22: 0 | J22: 0 | K22: 0
B23: 13 | C23: 13. 유형자산 | D23: =HYPERLINK("#'13'!A1","바로가기") | E23: =SUMPRODUCT(--ISNUMBER('13'!B10:B10))+SUMPRODUCT(--ISNUMBER('13'!B18:B18))+SUMPRODUCT(--ISNUMBER('13'!B28:B28))+SUMPRODUCT(--ISNUMBER('13'!B37:B37))+SUMPRODUCT(--ISNUMBER('13'!B45:B45))+SUMPRODUCT(--ISNUMBER('13'!C10:C10))+SUMPRODUCT(--ISNUMBER('13'!C18:C18))+SUMPRODUCT(--ISNUMBER('13'!C28:C28))+SUMPRODUCT(--ISNUMBER('13'!C37:C37))+SUMPRODUCT(--ISNUMBER('13'!C45:C45))+SUMPRODUCT(--ISNUMBER('13'!D10:D10))+SUMPRODUCT(--ISNUMBER('13'!D18:D18))+SUMPRODUCT(--ISNUMBER('13'!D28:D28))+SUMPRODUCT(--ISNUMBER('13'!D37:D37))+SUMPRODUCT(--ISNUMBER('13'!E10:E10))+SUMPRODUCT(--ISNUMBER('13'!E18:E18))+SUMPRODUCT(--ISNUMBER('13'!E28:E28))+SUMPRODUCT(--ISNUMBER('13'!E37:E37))+SUMPRODUCT(--ISNUMBER('13'!F10:F10))+SUMPRODUCT(--ISNUMBER('13'!F18:F18))+SUMPRODUCT(--ISNUMBER('13'!F28:F28))+SUMPRODUCT(--ISNUMBER('13'!F37:F37))+SUMPRODUCT(--ISNUMBER('13'!G10:G10))+SUMPRODUCT(--ISNUMBER('13'!G18:G18))+SUMPRODUCT(--ISNUMBER('13'!G28:G28))+SUMPRODUCT(--ISNUMBER('13'!G37:G37))+SUMPRODUCT(--ISNUMBER('13'!H10:H10))+SUMPRODUCT(--ISNUMBER('13'!H18:H18))+SUMPRODUCT(--ISNUMBER('13'!H28:H28))+SUMPRODUCT(--ISNUMBER('13'!H37:H37))+SUMPRODUCT(--ISNUMBER('13'!I10:I10))+SUMPRODUCT(--ISNUMBER('13'!I18:I18))+SUMPRODUCT(--ISNUMBER('13'!I28:I28))+SUMPRODUCT(--ISNUMBER('13'!I37:I37)) | F23: 0 | G23: =SUMPRODUCT(--ISNUMBER('13'!B50:B50)) | H23: 0 | I23: 0 | J23: 0 | K23: 0
B24: 14 | C24: 14. 리스 | D24: =HYPERLINK("#'14'!A1","바로가기") | E24: =SUMPRODUCT(--ISNUMBER('14'!B10:B10))+SUMPRODUCT(--ISNUMBER('14'!B19:B19))+SUMPRODUCT(--ISNUMBER('14'!B28:B28))+SUMPRODUCT(--ISNUMBER('14'!B37:B37))+SUMPRODUCT(--ISNUMBER('14'!B47:B47))+SUMPRODUCT(--ISNUMBER('14'!C19:C19))+SUMPRODUCT(--ISNUMBER('14'!C37:C37))+SUMPRODUCT(--ISNUMBER('14'!C47:C47))+SUMPRODUCT(--ISNUMBER('14'!D10:D10))+SUMPRODUCT(--ISNUMBER('14'!D19:D19))+SUMPRODUCT(--ISNUMBER('14'!D28:D28))+SUMPRODUCT(--ISNUMBER('14'!D37:D37))+SUMPRODUCT(--ISNUMBER('14'!E10:E10))+SUMPRODUCT(--ISNUMBER('14'!E19:E19))+SUMPRODUCT(--ISNUMBER('14'!E28:E28))+SUMPRODUCT(--ISNUMBER('14'!E37:E37))+SUMPRODUCT(--ISNUMBER('14'!F7:F9))+SUMPRODUCT(--ISNUMBER('14'!F16:F18))+SUMPRODUCT(--ISNUMBER('14'!F28:F28))+SUMPRODUCT(--ISNUMBER('14'!F37:F37))+SUMPRODUCT(--ISNUMBER('14'!G28:G28))+SUMPRODUCT(--ISNUMBER('14'!G37:G37))+SUMPRODUCT(--ISNUMBER('14'!H37:H37))+SUMPRODUCT(--ISNUMBER('14'!I25:I27))+SUMPRODUCT(--ISNUMBER('14'!I34:I36)) | F24: 0 | G24: =SUMPRODUCT(--ISNUMBER('14'!B52:B52)) | H24: 0 | I24: 0 | J24: 0 | K24: 0
B25: 15 | C25: 15. 무형자산 | D25: =HYPERLINK("#'15'!A1","바로가기") | E25: =SUMPRODUCT(--ISNUMBER('15'!B9:B9))+SUMPRODUCT(--ISNUMBER('15'!C9:C9)) | F25: 0 | G25: =SUMPRODUCT(--ISNUMBER('15'!B14:B14)) | H25: 0 | I25: 0 | J25: 0 | K25: 0
B26: 16 | C26: 16. 매입채무 및 기타지급채무 | D26: =HYPERLINK("#'16'!A1","바로가기") | E26: =SUMPRODUCT(--ISNUMBER('16'!B12:B13))+SUMPRODUCT(--ISNUMBER('16'!C12:C13)) | F26: 0 | G26: =SUMPRODUCT(--ISNUMBER('16'!B17:B18)) | H26: 0 | I26: 0 | J26: 0 | K26: 0
B27: 17 | C27: 17. 기타부채 | D27: =HYPERLINK("#'17'!A1","바로가기") | E27: =SUMPRODUCT(--ISNUMBER('17'!B16:B17))+SUMPRODUCT(--ISNUMBER('17'!B30:B30))+SUMPRODUCT(--ISNUMBER('17'!C16:C17))+SUMPRODUCT(--ISNUMBER('17'!C29:C30))+SUMPRODUCT(--ISNUMBER('17'!D29:D30))+SUMPRODUCT(--ISNUMBER('17'!E29:E30))+SUMPRODUCT(--ISNUMBER('17'!F23:F25))+SUMPRODUCT(--ISNUMBER('17'!F28:F28)) | F27: 0 | G27: =SUMPRODUCT(--ISNUMBER('17'!B35:B35)) | H27: 0 | I27: 0 | J27: 0 | K27: 0
B28: 18 | C28: 18. 종업원급여 | D28: =HYPERLINK("#'18'!A1","바로가기") | E28: =SUMPRODUCT(--ISNUMBER('18'!B9:B9))+SUMPRODUCT(--ISNUMBER('18'!B33:B35))+SUMPRODUCT(--ISNUMBER('18'!B43:B43))+SUMPRODUCT(--ISNUMBER('18'!B85:B85))+SUMPRODUCT(--ISNUMBER('18'!C9:C9))+SUMPRODUCT(--ISNUMBER('18'!C33:C35))+SUMPRODUCT(--ISNUMBER('18'!C43:C43))+SUMPRODUCT(--ISNUMBER('18'!C85:C85))+SUMPRODUCT(--ISNUMBER('18'!D33:D35))+SUMPRODUCT(--ISNUMBER('18'!E33:E35))+SUMPRODUCT(--ISNUMBER('18'!F33:F35))+SUMPRODUCT(--ISNUMBER('18'!G33:G35)) | F28: 0 | G28: 0 | H28: 0 | I28: 0 | J28: 0 | K28: 0
B29: 19 | C29: 19. 법인세비용 | D29: =HYPERLINK("#'19'!A1","바로가기") | E29: =SUMPRODUCT(--ISNUMBER('19'!B18:B18))+SUMPRODUCT(--ISNUMBER('19'!B46:B47))+SUMPRODUCT(--ISNUMBER('19'!B74:B75))+SUMPRODUCT(--ISNUMBER('19'!B99:B100))+SUMPRODUCT(--ISNUMBER('19'!C18:C18))+SUMPRODUCT(--ISNUMBER('19'!C46:C47))+SUMPRODUCT(--ISNUMBER('19'!C74:C75))+SUMPRODUCT(--ISNUMBER('19'!C99:C100))+SUMPRODUCT(--ISNUMBER('19'!D18:D18))+SUMPRODUCT(--ISNUMBER('19'!D74:D74))+SUMPRODUCT(--ISNUMBER('19'!D99:D99))+SUMPRODUCT(--ISNUMBER('19'!E18:E18))+SUMPRODUCT(--ISNUMBER('19'!E74:E75))+SUMPRODUCT(--ISNUMBER('19'!E99:E100))+SUMPRODUCT(--ISNUMBER('19'!F18:F18))+SUMPRODUCT(--ISNUMBER('19'!F54:F66))+SUMPRODUCT(--ISNUMBER('19'!F68:F73))+SUMPRODUCT(--ISNUMBER('19'!F81:F91))+SUMPRODUCT(--ISNUMBER('19'!F93:F98))+SUMPRODUCT(--ISNUMBER('19'!G18:G18)) | F29: 0 | G29: =SUMPRODUCT(--ISNUMBER('19'!B105:B105)) | H29: 0 | I29: 0 | J29: 0 | K29: 0
B30: 20 | C30: 20. 자본금 | D30: =HYPERLINK("#'20'!A1","바로가기") | E30: 0 | F30: 0 | G30: 0 | H30: 0 | I30: 0 | J30: 0 | K30: 0
B31: 21 | C31: 21. 자본잉여금 | D31: =HYPERLINK("#'21'!A1","바로가기") | E31: =SUMPRODUCT(--ISNUMBER('21'!B9:B9))+SUMPRODUCT(--ISNUMBER('21'!C9:C9)) | F31: 0 | G31: =SUMPRODUCT(--ISNUMBER('21'!B13:B13)) | H31: 0 | I31: 0 | J31: 0 | K31: 0
B32: 22 | C32: 22. 주식기준보상 | D32: =HYPERLINK("#'22'!A1","바로가기") | E32: 0 | F32: 0 | G32: 0 | H32: 0 | I32: 0 | J32: 0 | K32: 0
B33: 23 | C33: 23. 기타포괄손익누계액 및 기타자본항목 | D33: =HYPERLINK("#'23'!A1","바로가기") | E33: =SUMPRODUCT(--ISNUMBER('23'!B15:B15))+SUMPRODUCT(--ISNUMBER('23'!B24:B24))+SUMPRODUCT(--ISNUMBER('23'!C15:C15))+SUMPRODUCT(--ISNUMBER('23'!C24:C24)) | F33: 0 | G33: 0 | H33: 0 | I33: 0 | J33: 0 | K33: 0
B34: 24 | C34: 24. 이익잉여금 | D34: =HYPERLINK("#'24'!A1","바로가기") | E34: =SUMPRODUCT(--ISNUMBER('24'!B9:B9))+SUMPRODUCT(--ISNUMBER('24'!C9:C9)) | F34: 0 | G34: =SUMPRODUCT(--ISNUMBER('24'!B27:B27)) | H34: 0 | I34: 0 | J34: 0 | K34: 0
B35: 25 | C35: 25. 고객과의 계약에서 생기는 수익 및 관련 계약자산과 계약부채 | D35: =HYPERLINK("#'25'!A1","바로가기") | E35: =SUMPRODUCT(--ISNUMBER('25'!B9:B9))+SUMPRODUCT(--ISNUMBER('25'!B24:B26))+SUMPRODUCT(--ISNUMBER('25'!C9:C9))+SUMPRODUCT(--ISNUMBER('25'!C24:C26)) | F35: 0 | G35: =SUMPRODUCT(--ISNUMBER('25'!B38:B38)) | H35: 0 | I35: 0 | J35: 0 | K35: 0
B36: 26 | C36: 26. 매출원가 및 비용의 성격별 분류 | D36: =HYPERLINK("#'26'!A1","바로가기") | E36: =SUMPRODUCT(--ISNUMBER('26'!B10:B10))+SUMPRODUCT(--ISNUMBER('26'!B23:B23))+SUMPRODUCT(--ISNUMBER('26'!B34:B34))+SUMPRODUCT(--ISNUMBER('26'!C10:C10))+SUMPRODUCT(--ISNUMBER('26'!C23:C23))+SUMPRODUCT(--ISNUMBER('26'!C34:C34)) | F36: 0 | G36: =SUMPRODUCT(--ISNUMBER('26'!B38:B38)) | H36: 0 | I36: 0 | J36: 0 | K36: 0
B37: 27 | C37: 27. 판매비와일반관리비 | D37: =HYPERLINK("#'27'!A1","바로가기") | E37: =SUMPRODUCT(--ISNUMBER('27'!B18:B18))+SUMPRODUCT(--ISNUMBER('27'!C18:C18)) | F37: 0 | G37: =SUMPRODUCT(--ISNUMBER('27'!B22:B22)) | H37: 0 | I37: 0 | J37: 0 | K37: 0
B38: 28 | C38: 28. 금융수익 및 금융비용 | D38: =HYPERLINK("#'28'!A1","바로가기") | E38: =SUMPRODUCT(--ISNUMBER('28'!B16:B17))+SUMPRODUCT(--ISNUMBER('28'!C16:C17)) | F38: 0 | G38: =SUMPRODUCT(--ISNUMBER('28'!B21:B22)) | H38: 0 | I38: 0 | J38: 0 | K38: 0
B39: 29 | C39: 29. 기타영업외수익 및 기타영업외비용 | D39: =HYPERLINK("#'29'!A1","바로가기") | E39: =SUMPRODUCT(--ISNUMBER('29'!B12:B12))+SUMPRODUCT(--ISNUMBER('29'!B21:B21))+SUMPRODUCT(--ISNUMBER('29'!C12:C12))+SUMPRODUCT(--ISNUMBER('29'!C21:C21)) | F39: 0 | G39: =SUMPRODUCT(--ISNUMBER('29'!B25:B26)) | H39: 0 | I39: 0 | J39: 0 | K39: 0
B40: 30 | C40: 30. 주당이익 | D40: =HYPERLINK("#'30'!A1","바로가기") | E40: 0 | F40: 0 | G40: =SUMPRODUCT(--ISNUMBER('30'!B27:B27)) | H40: 0 | I40: 0 | J40: 0 | K40: 0
B41: 31 | C41: 31. 배당금 | D41: =HYPERLINK("#'31'!A1","바로가기") | E41: 0 | F41: 0 | G41: 0 | H41: 0 | I41: 0 | J41: 0 | K41: 0
B42: 32 | C42: 32. 현금흐름표 | D42: =HYPERLINK("#'32'!A1","바로가기") | E42: =SUMPRODUCT(--ISNUMBER('32'!B62:B63))+SUMPRODUCT(--ISNUMBER('32'!C62:C62))+SUMPRODUCT(--ISNUMBER('32'!F62:F63)) | F42: 0 | G42: =SUMPRODUCT(--ISNUMBER('32'!B67:B68)) | H42: 0 | I42: 0 | J42: 0 | K42: 0
...

Sheet BS
A1: 재무상태표 | L1: =HYPERLINK("#총괄표!A1","◀ 총괄표")
A2: 제 24(당) 기 / 제 23(전) 기
A3: (단위: 원)
A5: 과 목 | B5: 제 24(당) 기 | C5: 제 23(전) 기 | E5: 비 고
A6: 자산
A7: Ⅰ.유동자산 | B7: 15529132600 | C7: 13060257701
A8: 현금및현금성자산 | B8: 4026179709 | C8: 7065892198
A9: 매출채권 | B9: 6694059480 | C9: 2770373677
A10: 기타채권 | B10: 1295982716 | C10: 383573156
A11: 기타유동자산 | B11: 1860744304 | C11: 1345711030
A12: 재고자산 | B12: 289048521 | C12: 488767640
A13: 당기손익-공정가치 측정 금융자산 | B13: 1363117870 | C13: 1005940000
A14: Ⅱ.비유동자산 | B14: 12183259767 | C14: 10814852026
A15: 순확정급여자산 | B15: 142908857 | C15: 149436722
A16: 기타포괄손익-공정가치 측정 금융자산 | B16: 1863008916 | C16: 1117639800
A17: 당기손익-공정가치 측정 금융자산 | B17: 799476081 | C17: 297963428
A18: 기타비유동채권 | B18: 44750000 | C18: 634716290
... A23: 자산총계 | B23: 27712392367 | C23: 23875109727
A24: 부채
A25: Ⅰ.유동부채 | B25: 7864031023 | C25: 4731407030
A26: 매입채무 | B26: 4092018817 | C26: 1080656572
A27: 기타지급채무 | B27: 1909750882 | C27: 2655792531
A28: 당기법인세부채 | B28: 452086500 | C28: 289194234
A29: 기타유동부채 | B29: 1290888565 | C29: 528762533
A30: 리스부채 | B30: 119286259 | C30: 177001160
A31: Ⅱ.비유동부채 | B31: 167647469 | C31: 265381804
A32: 기타장기종업웝급여부채 | B32: 167647469 | C32: 126095545
A33: 기타비유동부채 | C33: 20000000
A34: 장기리스부채 | C34: 119286259
A35: 부채총계 | B35: 8031678492 | C35: 4996788834
A36: 자본
A37: Ⅰ.자본금 | B37: 6000000000 | C37: 6000000000
A38: Ⅱ.자본잉여금 | B38: 2412507508 | C38: 2412507508
A39: Ⅲ.기타자본구성요소 | B39: -113906642 | C39: -146286642
A40: Ⅳ.기타포괄손익누계액 | B40: -796532768 | C40: -1101842923
A41: Ⅴ.이익잉여금 | B41: 12178645777 | C41: 11713942950
A42: 자본총계 | B42: 19680713875 | C42: 18878320893
A43: 부채및자본총계 | B43: 27712392367 | C43: 23875109727
A45: ■ 푸팅 검증 (소계 − Σ직계 항목)
A46: Ⅰ.유동자산 (행 7 = Σ행 8~13) | B46: =IF(ABS(B7-((B8+B9+B10+B11+B12+B13)))<0.5,TRUE,B7-((B8+B9+B10+B11+B12+B13))) | C46: =IF(ABS(C7-((C8+C9+C10+C11+C12+C13)))<0.5,TRUE,C7-((C8+C9+C10+C11+C12+C13)))
...

Sheet PL
A1: 포괄손익계산서 | L1: =HYPERLINK("#총괄표!A1","◀ 총괄표")
A2: 제 24(당) 기 / 제 23(전) 기
A3: (단위: 원)
A5: 과 목 | B5: 제 24(당) 기 | C5: 제 23(전) 기 | E5: 비 고
A6: Ⅰ.매출 | B6: 24863482484 | C6: 29539354935
A7: Ⅱ.매출원가 | B7: 19674721789 | C7: 24560558905
A8: Ⅲ.매출총이익 | B8: 5188760695 | C8: 4978796030
A9: 판매비와관리비 | B9: 3125550277 | C9: 2995652407
A10: Ⅳ.영업이익 | B10: 2063210418 | C10: 1983143623
A11: 금융수익 | B11: 781875870 | C11: 273577008
A12: 금융비용 | B12: 105257667 | C12: 57186407
A13: 기타영업외수익 | B13: 116473039 | C13: 269895554
A14: 기타영업외비용 | B14: 93737180 | C14: 46949376
A15: Ⅴ.법인세비용차감전순이익 | B15: 2762564480 | C15: 2422480402
A16: 법인세비용 | B16: 235114420 | C16: 423305542
A17: Ⅵ.당기순이익 | B17: 2527450060 | C17: 1999174860
... A23: Ⅷ.총포괄손익 | B23: 2930012982 | C23: 1586027159
A24: Ⅸ.주당이익
A25: 기본주당이익 | B25: 211 | C25: 167
A26: 희석주당이익 | B26: 210 | C26: 167
A28: ■ 푸팅 검증 (소계 − Σ직계 항목)
A29: 당기손익으로 재분류되지 않는 항목 (행 19 = Σ행 20~22) | B29: =IF(ABS(B19-((B20+B21+B22)))<0.5,TRUE,B19-((B20+B21+B22))) | C29: =IF(ABS(C19-((C20+C21+C22)))<0.5,TRUE,C19-((C20+C21+C22)))
A31: ■ 산식 검증 (비단순합)
A32: 매출총이익 = 매출액 − 매출원가 (행 8) | B32: =IF(ABS(B8-(+B6-B7))<0.5,TRUE,B8-(+B6-B7)) | C32: =IF(ABS(C8-(+C6-C7))<0.5,TRUE,C8-(+C6-C7))
A33: 영업이익 = 매출총이익 − 판매비와관리비 (행 10) | B33: =IF(ABS(B10-(+B8-B9))<0.5,TRUE,B10-(+B8-B9)) | C33: =IF(ABS(C10-(+C8-C9))<0.5,TRUE,C10-(+C8-C9))
A34: 법인세비용차감전순이익 = 영업이익 + 사이 수익 항목 − 사이 비용 항목 (행 15) | B34: =IF(ABS(B15-(+B10+B11-B12+B13-B14))<0.5,TRUE,B15-(+B10+B11-B12+B13-B14)) | C34: =IF(ABS(C15-(+C10+C11-C12+C13-C14))<0.5,TRUE,C15-(+C10+C11-C12+C13-C14))
A35: 당기순이익 = 법인세비용차감전순이익 − 법인세비용 (행 17) | B35: =IF(ABS(B17-(+B15-B16))<0.5,TRUE,B17-(+B15-B16)) | C35: =IF(ABS(C17-(+C15-C16))<0.5,TRUE,C17-(+C15-C16))
A36: 총포괄손익 = 당기순이익 + 기타포괄손익 (행 23) | B36: =IF(ABS(B23-(+B17+B18))<0.5,TRUE,B23-(+B17+B18)) | C36: =IF(ABS(C23-(+C17+C18))<0.5,TRUE,C23-(+C17+C18))
A37: 기타포괄손익 = 당기손익으로 재분류되지 않는 항목 (행 18) | B37: =IF(ABS(B18-(+B19))<0.5,TRUE,B18-(+B19)) | C37: =IF(ABS(C18-(+C19))<0.5,TRUE,C18-(+C19))

Sheet CE
A1: 자본변동표 | P1: =HYPERLINK("#총괄표!A1","◀ 총괄표")
A3: (단위: 원)
A5: 과 목 | B5: 자본금 | C5: 자본잉여금 | D5: 기타자본구성요소 | E5: 기타포괄손익누계액 | F5: 이익잉여금 | G5: 총 계 | H5: 행합검증 (총계−Σ) | J5: 비 고
A6: 2024년 1월 1일(전기초) | B6: 6000000000 | C6: 2412507508 | D6: -171214805 | E6: -763802763 | F6: 11949875631 | G6: 19427365571 | H6: =IF(ABS(G6-(B6+C6+D6+E6+F6))<0.5,TRUE,G6-(B6+C6+D6+E6+F6))
A7: 총포괄손익
A8: 당기순이익 | F8: 1999174860 | G8: 1999174860 | H8: =IF(ABS(G8-(B8+C8+D8+E8+F8))<0.5,TRUE,G8-(B8+C8+D8+E8+F8))
A9: 기타포괄손익
A10: 순확정급여자산의 재측정요소 | F10: -99073312 | G10: -99073312 | H10: =IF(ABS(G10-(B10+C10+D10+E10+F10))<0.5,TRUE,G10-(B10+C10+D10+E10+F10))
A11: 기타포괄손익-공정가치 측정지분상품 평가손익 | E11: -314074389 | G11: -314074389 | H11: =IF(ABS(G11-(B11+C11+D11+E11+F11))<0.5,TRUE,G11-(B11+C11+D11+E11+F11))
A12: 총포괄손익 합계 | E12: -314074389 | F12: 1900101548 | G12: 1586027159 | H12: =IF(ABS(G12-(B12+C12+D12+E12+F12))<0.5,TRUE,G12-(B12+C12+D12+E12+F12))
A13: 기타포괄손익-공정가치 측정 지분상품 처분에 따른 대체 | E13: -23965771 | F13: 23965771
A14: 소유주와의 거래
A15: 배당금 지급 | F15: -2160000000 | G15: -2160000000 | H15: =IF(ABS(G15-(B15+C15+D15+E15+F15))<0.5,TRUE,G15-(B15+C15+D15+E15+F15))
A16: 주식보상비용 | D16: 24928163 | G16: 24928163 | H16: =IF(ABS(G16-(B16+C16+D16+E16+F16))<0.5,TRUE,G16-(B16+C16+D16+E16+F16))
A17: 2024년 12월 31일(전기말) | B17: 6000000000 | C17: 2412507508 | D17: -146286642 | E17: -1101842923 | F17: 11713942950 | G17: 18878320893 | H17: =IF(ABS(G17-(B17+C17+D17+E17+F17))<0.5,TRUE,G17-(B17+C17+D17+E17+F17))
A18: 2025년 1월 1일(당기초) | B18: 6000000000 | C18: 2412507508 | D18: -146286642 | E18: -1101842923 | F18: 11713942950 | G18: 18878320893 | H18: =IF(ABS(G18-(B18+C18+D18+E18+F18))<0.5,TRUE,G18-(B18+C18+D18+E18+F18))
A19: 총포괄손익
A20: 당기순이익 | F20: 2527450060 | G20: 2527450060 | H20: =IF(ABS(G20-(B20+C20+D20+E20+F20))<0.5,TRUE,G20-(B20+C20+D20+E20+F20))
A21: 기타포괄손익
A22: 순확정급여자산의 재측정요소 | F22: 59449222 | G22: 59449222 | H22: =IF(ABS(G22-(B22+C22+D22+E22+F22))<0.5,TRUE,G22-(B22+C22+D22+E22+F22))
A23: 기타포괄손익-공정가치 측정지분상품 평가손익 | E23: 343113700 | G23: 343113700 | H23: =IF(ABS(G23-(B23+C23+D23+E23+F23))<0.5,TRUE,G23-(B23+C23+D23+E23+F23))
A24: 총포괄손익 합계 | E24: 343113700 | F24: 2586899282 | G24: 2930012982 | H24: =IF(ABS(G24-(B24+C24+D24+E24+F24))<0.5,TRUE,G24-(B24+C24+D24+E24+F24))
A25: 기타포괄손익-공정가치 측정 지분상품 처분에 따른 대체 | E25: -37803545 | F25: 37803545
A26: 소유주와의 거래
A27: 배당금 지급 | F27: -2160000000 | G27: -2160000000 | H27: =IF(ABS(G27-(B27+C27+D27+E27+F27))<0.5,TRUE,G27-(B27+C27+D27+E27+F27))
A28: 주식보상비용 | D28: 32380000 | G28: 32380000 | H28: =IF(ABS(G28-(B28+C28+D28+E28+F28))<0.5,TRUE,G28-(B28+C28+D28+E28+F28))
A29: 2025년 12월 31일(당기말) | B29: 6000000000 | C29: 2412507508 | D29: -113906642 | E29: -796532768 | F29: 12178645777 | G29: 19680713875 | H29: =IF(ABS(G29-(B29+C29+D29+E29+F29))<0.5,TRUE,G29-(B29+C29+D29+E29+F29))
A31: ■ 푸팅 검증 (소계 − Σ직계 항목)
A32: 2024년 12월 31일(전기말) = 2024년 1월 1일(전기초) + 변동 (행 6~17) | B32: =IF(ABS(B17-(B6+B8+B10+B11+B13+B15+B16))<0.5,TRUE,B17-(B6+B8+B10+B11+B13+B15+B16)) | C32: =IF(ABS(C17-(C6+C8+C10+C11+C13+C15+C16))<0.5,TRUE,C17-(C6+C8+C10+C11+C13+C15+C16)) | D32: =IF(ABS(D17-(D6+D8+D10+D11+D13+D15+D16))<0.5,TRUE,D17-(D6+D8+D10+D11+D13+D15+D16)) | E32: =IF(ABS(E17-(E6+E8+E10+E11+E13+E15+E16))<0.5,TRUE,E17-(E6+E8+E10+E11+E13+E15+E16)) | F32: =IF(ABS(F17-(F6+F8+F10+F11+F13+F15+F16))<0.5,TRUE,F17-(F6+F8+F10+F11+F13+F15+F16)) | G32: =IF(ABS(G17-(G6+G8+G10+G11+G13+G15+G16))<0.5,TRUE,G17-(G6+G8+G10+G11+G13+G15+G16))
A33: 2025년 1월 1일(당기초) = 2024년 12월 31일(전기말) + 변동 (행 17~18) | B33: =IF(ABS(B18-(B17))<0.5,TRUE,B18-(B17)) | C33: =IF(ABS(C18-(C17))<0.5,TRUE,C18-(C17)) | D33: =IF(ABS(D18-(D17))<0.5,TRUE,D18-(D17)) | E33: =IF(ABS(E18-(E17))<0.5,TRUE,E18-(E17)) | F33: =IF(ABS(F18-(F17))<0.5,TRUE,F18-(F17)) | G33: =IF(ABS(G18-(G17))<0.5,TRUE,G18-(G17))
A34: 2025년 12월 31일(당기말) = 2025년 1월 1일(당기초) + 변동 (행 18~29) | B34: =IF(ABS(B29-(B18+B20+B22+B23+B25+B27+B28))<0.5,TRUE,B29-(B18+B20+B22+B23+B25+B27+B28)) | C34: =IF(ABS(C29-(C18+C20+C22+C23+C25+C27+C28))<0.5,TRUE,C29-(C18+C20+C22+C23+C25+C27+C28)) | D34: =IF(ABS(D29-(D18+D20+D22+D23+D25+D27+D28))<0.5,TRUE,D29-(D18+D20+D22+D23+D25+D27+D28)) | E34: =IF(ABS(E29-(E18+E20+E22+E23+E25+E27+E28))<0.5,TRUE,E29-(E18+E20+E22+E23+E25+E27+E28)) | F34: =IF(ABS(F29-(F18+F20+F22+F23+F25+F27+F28))<0.5,TRUE,F29-(F18+F20+F22+F23+F25+F27+F28)) | G34: =IF(ABS(G29-(G18+G20+G22+G23+G25+G27+G28))<0.5,TRUE,G29-(G18+G20+G22+G23+G25+G27+G28))
A36: ■ 크로스 참조
A37: 자본변동표 기말 총계 = 재무상태표 자본총계 (당기) | B37: =IF(ABS(G29-'BS'!B42)<0.5,TRUE,G29-'BS'!B42) | C37: → BS!B42
A38: 자본변동표 순이익 = 손익계산서 순이익 (기간 1) | B38: =IF(ABS(F20-'PL'!B17)<0.5,TRUE,F20-'PL'!B17) | C38: → PL!B17
A39: 자본변동표 순이익 = 손익계산서 순이익 (기간 2) | B39: =IF(ABS(F8-'PL'!C17)<0.5,TRUE,F8-'PL'!C17) | C39: → PL!C17

Sheet CF
A1: 현금흐름표 | L1: =HYPERLINK("#총괄표!A1","◀ 총괄표")
A2: 제 24(당) 기 / 제 23(전) 기
A3: (단위: 원)
A5: 과 목 | B5: 제 24(당) 기 | C5: 제 23(전) 기 | E5: 비 고
A6: Ⅰ.영업활동으로 인한 현금흐름 | B6: 62790389 | C6: 2355960139
A7: 영업으로부터 창출된 현금흐름 | B7: 109355005 | C7: 2631298470
A8: 이자의수취 | B8: 159351163 | C8: 182783651
A9: 이자의지급 | B9: -8232160 | C9: -61042963
A10: 배당의수취 | B10: 70691884 | C10: 30420392
A11: 법인세납부 | B11: -268375503 | C11: -427499411
A12: Ⅱ.투자활동으로 인한 현금흐름 | B12: -763129087 | C12: 828645529
A13: 단기대여금의 회수 | B13: 41476720 | C13: 55666720
A14: 장기대여금의 회수 | B14: 29499880
A15: 임차보증금의 감소 | C15: 1870593
A16: 유형자산의 처분 | B16: 5554546
A17: 당기손익-공정가치 측정 금융자산의 처분 | B17: 5441040815
A18: 기타포괄손익-공정가치 측정 금융자산의 처분 | B18: 599000448 | C18: 2777550905
A19: 단기대여금의 대여 | B19: -6000000 | C19: -18750000
A20: 장기대여금의 대여 | B20: -54000000 | C20: -31250000
A21: 유형자산의 취득 | B21: -96611000 | C21: -195206073
A22: 당기손익-공정가치 측정 금융자산의 취득 | B22: -5798291786 | C22: -1000000000
A23: 기타포괄손익-공정가치 측정 금융자산의 취득 | B23: -924798710 | C23: -761236616
A24: Ⅲ.재무활동으로 인한 현금흐름 | B24: -2337001160 | C24: -3678045164
A25: 차입금의 상환 | C25: -1340000000
A26: 배당금지급 | B26: -2160000000 | C26: -2160000000
A27: 리스부채의 상환 | B27: -177001160 | C27: -178045164
A28: Ⅳ.현금및현금성자산의 감소 | B28: -3037339858 | C28: -493439496
A29: Ⅴ.기초 현금및현금성자산 | B29: 7065892198 | C29: 7557380795
A30: Ⅵ.현금및현금성자산의 환율변동효과 | B30: -2372631 | C30: 1950899
A31: Ⅶ.기말 현금및현금성자산 | B31: 4026179709 | C31: 7065892198
A33: ■ 푸팅 검증 (소계 − Σ직계 항목)
A34: Ⅰ.영업활동으로 인한 현금흐름 (행 6 = Σ행 7~11) | B34: =IF(ABS(B6-((B7+B8+B9+B10+B11)))<0.5,TRUE,B6-((B7+B8+B9+B10+B11))) | C34: =IF(ABS(C6-((C7+C8+C9+C10+C11)))<0.5,TRUE,C6-((C7+C8+C9+C10+C11)))
A35: Ⅱ.투자활동으로 인한 현금흐름 (행 12 = Σ행 13~23) | B35: =IF(ABS(B12-((B13+B14+B15+B16+B17+B18+B19+B20+B21+B22+B23)))<0.5,TRUE,B12-((B13+B14+B15+B16+B17+B18+B19+B20+B21+B22+B23))) | C35: =IF(ABS(C12-((C13+C14+C15+C16+C17+C18+C19+C20+C21+C22+C23)))<0.5,TRUE,C12-((C13+C14+C15+C16+C17+C18+C19+C20+C21+C22+C23)))
A36: Ⅲ.재무활동으로 인한 현금흐름 (행 24 = Σ행 25~27) | B36: =IF(ABS(B24-((B25+B26+B27)))<0.5,TRUE,B24-((B25+B26+B27))) | C36: =IF(ABS(C24-((C25+C26+C27)))<0.5,TRUE,C24-((C25+C26+C27)))
A38: ■ 산식 검증 (비단순합)
A39: Ⅳ.현금및현금성자산의 감소 = 직전 소계 + 사이 항목 (행 28) | B39: =IF(ABS(B28-(+B6+B12+B24))<0.5,TRUE,B28-(+B6+B12+B24)) | C39: =IF(ABS(C28-(+C6+C12+C24))<0.5,TRUE,C28-(+C6+C12+C24))
A40: Ⅶ.기말 현금및현금성자산 = 직전 소계 + 사이 항목 (행 31) | B40: =IF(ABS(B31-(+B28+B29+B30))<0.5,TRUE,B31-(+B28+B29+B30)) | C40: =IF(ABS(C31-(+C28+C29+C30))<0.5,TRUE,C31-(+C28+C29+C30))

Sheet 1
A1: 1. 회사의 개요 | J1: =HYPERLINK("#총괄표!A1","◀ 총괄표")
A3: 주식회사 케이씨에스(이하 "당사")는 금융기관에 사용되는 중대형 서버 등의 제조, 판매 및 유지보수를 목적으로 한국지주(주)로부터 물적분할에 의하여 2002년 12월 1일 설립되었습니다. 당사는 경상북도 구미시 3공단1로 284(임수동)에 본점을 두고 있으며 서울특별시 마포구에 지점을 두고 있습니다.당사는 2009년 8월 31일자 임시주주총회의 결의에 의거 당사의 상호를 주식회사 케이씨아이에서 주식회사 케이씨에스로 변경하였습니다. 또한 당사는 2010년 4월 14일자로 한국거래소가 개설하는 코스닥(KOSDAQ)시장에 주식을 상장하였습니다.
A4: 당기말과 전기말 현재 당사의 주요 주주현황은 다음과 같습니다.
A5: 주주명 | B5: 당기말 | C5: 당기말 | D5: 전기말 | E5: 전기말
A6: 주주명 | B6: 주식수(주) | C6: 지분율 | D6: 주식수(주) | E6: 지분율
A7: 한국지주(주) | B7: 8000000 | C7: 66.67% | D7: 8000000 | E7: 66.67%
A8: 기 타 | B8: 4000000 | C8: 33.33% | D8: 4000000 | E8: 33.33%
A9: 합 계 | B9: 12000000 | C9: 100.00% | D9: 12000000 | E9: 100.00%
A10: └ 푸팅검증: 합 계(행 9) − Σ(행) | B10: =IF(ABS(B9-(SUM(B7:B8)))<0.5,TRUE,B9-(SUM(B7:B8))) | D10: =IF(ABS(D9-(SUM(D7:D8)))<0.5,TRUE,D9-(SUM(D7:D8)))

Sheet 2
A1: 2. 중요한 회계정책 | J1: =HYPERLINK("#총괄표!A1","◀ 총괄표")
A3: 다음은 재무제표 작성에 적용된 중요한 회계정책입니다. 이러한 정책은 별도의 언급이 없다면, 표시된 회계기간에 계속적으로 적용됩니다.
A4: 2.1 재무제표 작성 기준
A5: 당사의 재무제표는 한국채택국제회계기준(이하 "기업회계기준")에 따라 작성됐습니다. 한국채택국제회계기준은 국제회계기준위원회("IASB")가 발표한 기준서와 해석서 중 대한민국이 채택한 내용을 의미합니다.
A6: 재무제표는 다음을 제외하고는 역사적 원가에 기초하여 작성하였습니다.
A7: - | B7: 당기손익-공정가치로 측정되는 금융상품
A8: - | B8: 기타포괄손익-공정가치로 측정되는 금융상품
A9: - | B9: 확정급여채무의 현재가치에서 사외적립자산의 공정가치를 차감한 확정급여부채(자산)
A11: 기업회계기준은 재무제표 작성 시 중요한 회계추정의 사용을 허용하고 있으며, 회계정책을 적용함에 있어 경영진의 판단을 요구하고 있습니다. 보다 복잡하고 높은 수준의 판단이 필요한 부분이나 중요한 가정 및 추정이 필요한 부분은 주석 3에서 설명하고 있습니다.
A12: 2.2 회계정책과 공시의 변경
A13: 2.2.1 당사가 채택한 제ㆍ개정 기준서 및 해석서당사는 2025년 1월 1일로 개시하는 회계기간부터 다음의 제ㆍ개정 기준서 및 해석서를 신규로 적용하였습니다.(1) 기업회계기준서 제1021호 '환율변동효과' 개정 - 교환가능성의 결여당사는 2025년 1월 1일부터 통화의 교환가능성을 평가하고 다른 통화와 교환이 가능하지 않다면 현물환율을 추정하며 관련 정보를 공시하도록 하는 개정사항을 적용하였습니다. 동 개정사항은 2025년 1월 1일 이후 시작하는 회계연도부터 적용되며, 조기적용이 허용됩니다. 해당 기준서의 개정이 재무제표에 미치는 중요한 영향은 없습니다.
A14: 2.2.2 당사가 적용하지 않은 제ㆍ개정 기준서 및 해석서
A15: 제정ㆍ공표되었으나 2025년 1월 1일 이후 시작하는 회계연도에 시행일이 도래하지 아니한 주요 제ㆍ개정 기준서 및 해석서는 다음과 같습니다. 당사는 재무제표 작성시다음의 제ㆍ개정 기준서 및 해석서를 조기적용하지 아니하였습니다. 다음의 제ㆍ개정 기준서가 당사에 미치는 영향을 검토하고 있습니다. - 금융상품 분류와 측정 요구사항(기업회계기준서 제1107호 '금융상품: 공시', 제1109호 '금융상품')- 재무제표 표시와 공시의 제정(기업회계기준서 제1118호 '재무제표 표시와 공시')- 연차개선(기업회계기준서 제1007호 '현금흐름표', 제1107호 '금융상품: 공시', 제1109호 '금융상품', 제1110호 '연결재무제표')
A16: 2.3 외화환산
A17: (1) 기능통화와 표시통화
A18: 당사는 영업활동이 이뤄지는 주된 경제 환경에서의 통화("기능통화")를 적용하여 측정하고 있습니다. 당사의 기능통화는 대한민국 원화이며, 재무제표는 대한민국 원화로 표시되어 있습니다.
A19: (2) 외화거래와 보고기간말의 환산
A20: 외화거래는 거래일의 환율 또는 재측정되는 항목인 경우 평가일의 환율을 적용한 기능통화로 인식됩니다. 외화거래의 결제나 화폐성 외화 자산ㆍ부채의 환산에서 발생하는 외환차이는 당기손익으로 인식됩니다. 다만, 조건을 충족하는 현금흐름위험회피나 순투자의 위험회피의 효과적인 부분과 관련되거나 보고기업의 해외사업장에 대한 순투자의 일부인 화폐성항목에서 생기는 손익은 기타포괄손익으로 인식합니다.
A21: 차입금과 관련된 외환차이는 포괄손익계산서에 '금융비용'으로 표시되며, 다른 외환차이는 '기타영업외수익' 또는 '기타영업외비용'에 표시됩니다.
A22: 비화폐성 금융자산ㆍ부채로부터 발생하는 외환차이는 공정가치 변동손익의 일부로 보아 당기손익-공정가치 측정 지분상품으로부터 발생하는 외환차이는 당기손익으로, 기타포괄손익-공정가치 측정 지분상품의 외환차이는 기타포괄손익에 포함하여 인식됩니다.
... A53: 토지를 제외한 자산은 취득원가에서 잔존가치를 제외하고, 다음의 추정 경제적 내용연수에 걸쳐 정액법으로 상각됩니다.
A54: 과 목 | B54: 추정 내용연수
A55: 건물 | B55: 40년
A56: 구축물 | B56: 5년
A57: 기계장치 | B57: 4년
A58: 차량운반구 | B58: 4년
A59: 집기비품 | B59: 4년
A61: 유형자산의 감가상각방법과 잔존가치 및 경제적 내용연수는 매 회계연도 말에 재검토 되고 필요한 경우 추정의 변경으로 조정됩니다.
A62: 2.8 차입원가 적격자산을 취득 또는 건설하는데 발생한 차입원가는 해당 자산을 의도된 용도로 사용할 수 있도록 준비하는 기간 동안 자본화되고, 적격자산을 취득하기 위한 특정목적차입금의 일시적 운용에서 발생한 투자수익은 당 회계기간 동안 자본화 가능한 차입원가에서 차감됩니다. 기타 차입원가는 발생기간에 비용으로 인식됩니다.
A63: 2.9 무형자산
A64: 당사의 무형자산은 회원권으로서 최초 인식할 때 원가로 측정하며, 최초 인식 후에 원가에서 손상차손누계액을 차감한 금액을 장부금액으로 인식하고 있습니다. 동 회원권은 이를 이용할 수 있을 것으로 기대되는 기간에 대하여 예측가능한 제한이 없으므로 내용연수가 한정되지 않아 상각되지 않습니다.
A65: 2.10 투자부동산임대수익이나 투자차익을 목적으로 보유하고 있는 부동산은 투자부동산으로 분류됩니다. 투자부동산은 최초 인식시점에 원가로 측정되며, 최초 인식 후에는 원가에서 감가상각누계액과 손상차손누계액을 차감한 금액으로 표시됩니다.
A66: 2.11 비금융자산의 손상내용연수가 비한정인 무형자산에 대하여는 매년, 상각대상 자산에 대하여는 자산손상을 시사하는 징후가 있을 때 손상검사를 수행하고 있습니다. 손상차손은 회수가능액(사용가치 또는 처분부대원가를 차감한 공정가치 중 높은 금액)을 초과하는 장부금액만큼 인식되고 영업권 이외의 비금융자산에 대한 손상차손은 매 보고기간말에 환입가능성이 검토됩니다.
A67: 2.12 매입채무와 기타지급채무
A68: 매입채무와 기타지급채무는 당사가 보고기간말 전에 재화나 용역을 제공받았으나 지급되지 않은 부채입니다. 해당 채무는 무담보이며, 보통 인식 후 60일 이내에 지급됩니다. 매입채무와 기타지급채무는 지급기일이 보고기간 후 12개월 후가 아니라면 유동부채로 표시되었습니다. 해당 채무들은 최초에 공정가치로 인식되고 후속적으로 유효이자율법을 적용한 상각후원가로 측정됩니다.
A69: 2.13 금융부채 (1) 분류 및 측정당기손익-공정가치 측정 금융부채, 금융보증계약, 금융자산의 양도가 제거조건을 충족하지 못하는 경우에 발생하는 금융부채를 제외한 모든 비파생금융부채는 상각후원가로 측정하는 금융부채로 분류되고 있으며, 재무상태표 상 '매입채무'와 '기타지급채무' 등으로 표시됩니다.
A70: (2) 제거금융부채는 계약상 의무가 이행, 취소 또는 만료되어 소멸되거나 기존 금융부채의 조건이 실질적으로 변경된 경우에 재무상태표에서 제거됩니다. 소멸하거나 제3자에게 양도한 금융부채의 장부금액과 지급한 대가(양도한 비현금자산이나 부담한 부채를 포함)의 차액은 당기손익으로 인식합니다.2.14 충당부채과거사건의 결과로 현재의 법적의무나 의제의무가 존재하고, 그 의무를 이행하기 위한 자원의 유출가능성이 높으며, 당해 금액의 신뢰성 있는 추정이 가능한 경우 복구충당부채 및 소송충당부채 등을 인식하고 있습니다. 충당부채는 의무를 이행하기 위하여 예상되는 지출액의 현재가치로 측정되며, 시간경과로 인한 충당부채의 증가는 이자비용으로 인식됩니다.
A71: 2.15 당기법인세 및 이연법인세법인세비용은 당기법인세와 이연법인세로 구성됩니다. 법인세는 기타포괄손익이나 자본에 직접 인식된 항목과 관련된 금액은 해당 항목에서 직접 인식하며, 이를 제외하고는 당기손익으로 인식됩니다.당기법인세비용은 보고기간말 현재 제정되었거나 실질적으로 제정된 세법에 근거하여 측정합니다. 경영진은 적용 가능한 세법 규정이 해석에 따라 달라질 수 있는 상황에 대하여 당사가 세무신고 시 적용한 세무정책에 대하여 주기적으로 평가하고 있으며, 세무당국이 불확실한 법인세 처리를 수용할 가능성이 높은지 고려합니다. 당사는법인세 측정 시 가장 가능성이 높은 금액 또는 기댓값 중 불확실성의 해소를 더 잘 예측할 것으로 예상되는 방법을 사용하여 불확실성의 영향을 반영합니다.이연법인세는 자산과 부채의 장부금액과 세무기준액의 차이로 발생하는 일시적차이에 대하여 장부금액을 회수하거나 결제할 때의 예상 법인세효과로 인식됩니다. 다만,사업결합 이외의 거래에서 자산ㆍ부채를 최초로 인식할 때 발생하는 이연법인세 자산과 부채는 그 거래가 회계이익이나 과세소득에 영향을 미치지 않는다면 인식되지 않습니다.
A72: 이연법인세자산은 차감할 일시적차이가 사용될 수 있는 미래 과세소득의 발생가능성이 높은 경우에 인식됩니다.이연법인세 자산과 부채는 법적으로 당기법인세자산과 당기법인세부채를 상계할 수 있는 권리를 당사가 보유하고 있고, 이연법인세 자산과 부채가 동일한 과세당국에 의해서 부과되는 법인세와 관련된 경우에 상계합니다. 당기법인세 자산과 부채는 법적으로 상계할 수 있는 권리를 당사가 보유하고 있고, 순액으로 결제할 의도가 있거나 자산을 실현하는 동시에 부채를 결제하려는 의도가 있는 경우에 상계합니다.
... A83: 리스에서 생기는 자산과 부채는 최초에 현재가치기준으로 측정합니다. 리스부채는 다음 리스료의 순현재가치를 포함합니다.
...

Sheet 3
A1: 3. 중요한 회계추정 및 가정 | J1: =HYPERLINK("#총괄표!A1","◀ 총괄표")
A3: 재무제표 작성에는 미래에 대한 가정 및 추정이 요구되며 경영진은 당사의 회계정책을 적용하기 위해 판단이 요구됩니다. 추정 및 가정은 지속적으로 평가되며, 과거 경험과 현재의 상황에 비추어 합리적으로 예측가능한 미래의 사건을 고려하여 이루어집니다. 회계추정의 결과가 실제 결과와 동일한 경우는 드물 것이므로 중요한 조정을유발할 수 있는 유의적인 위험을 내포하고 있습니다.
A4: 다음 회계연도에 자산 및 부채 장부금액의 조정에 영향을 미칠 수 있는 경영진 판단과 유의적 위험에 대한 추정 및 가정은 다음과 같습니다. 일부 항목에 대한 유의적인 판단 및 추정에 대한 추가적인 정보는 개별 주석에 포함되어 있습니다.
A5: (1) 법인세당사의 과세소득에 대한 법인세는 세법 및 과세당국의 결정을 적용하여 산정되므로 최종 세효과를 산정하는 데에는 불확실성이 존재합니다(주석 19 참조).
A6: 당사는 이연법인세 측정 시 미래 예상 과세소득에 적용되는 예상평균세율을 추정하고 있으며, 이연법인세의 실현가능성 판단 시에는 예상되는 차감할 일시적차이, 예상과세소득, 이월세액공제의 사용가능성 등을 추정하고 있습니다.
A7: (2) 금융상품의 공정가치
A8: 활성시장에서 거래되지 않는 금융상품의 공정가치는 원칙적으로 평가기법을 사용하여 결정됩니다. 당사는 보고기간말 현재 중요한 시장상황에 기초하여 다양한 평가기법의 선택 및 가정에 대한 판단을 하고 있습니다(주석 5 참조).
A9: (3) 금융자산의 손상
A10: 금융자산의 손실충당금은 부도위험 및 기대손실률 등에 대한 가정에 기초하여 측정됩니다. 당사는 이러한 가정의 설정 및 손상모델에 사용되는 투입변수의 선정에 있어서 당사의 과거 경험, 현재 시장 상황, 재무보고일 기준의 미래전망정보 등을 고려하여 판단합니다(주석 4.1.2 참조).
A11: (4) 순확정급여부채(자산)
A12: 순확정급여부채(자산)의
A13: 현재가치는
A14: 보험수리적방식에
... A17: 요소들,특히 할인율의 변동에 영향을 받습니다(주석 18 참조).

Sheet 4
A1: 4. 재무위험관리 | J1: =HYPERLINK("#총괄표!A1","◀ 총괄표")
A3: 4.1 재무위험관리요소 당사는 여러 활동으로 인하여 시장위험(외환위험, 이자율위험, 가격위험), 신용위험 및 유동성위험과 같은 다양한 재무위험에 노출돼 있습니다. 당사의 전반적인 위험관리정책은 금융시장의 변동성에 초점을 맞추고 있으며 재무성과에 미치는 부정적 영향을 최소화하는데 중점을 두고 있습니다.재무위험관리의 대상이 되는 당사의 금융자산은 현금및현금성자산, 당기손익-공정가치 측정 금융자산, 기타포괄손익-공정가치 측정 금융자산, 매출채권 및 기타채권 등으로 구성되어 있으며 금융부채는 매입채무, 미지급금, 미지급비용 등으로 구성되어 있습니다.
A4: 4.1.1 시장위험
A5: (1) 외환위험당사는 기능통화인 원화 이외의 통화로 표시되는 거래로 인하여 환율변동위험에 노출되어 있습니다. 보고기간말 현재 외환 위험에 노출되어 있는 당사의 금융자산ㆍ부채의 내역의 원화환산 기준액은 다음과 같습니다.
B6: (단위: 천원)
A7: 구 분 | B7: 당기말 | C7: 전기말
A8: 외화자산 | B8: 외화자산 | C8: 외화자산
A9: 현금및현금성자산 | B9: 1657729 | C9: 65114
A10: 당기손익-공정가치 측정 금융자산 | B10: 966816 | C10: 0
A11: 기타포괄손익-공정가치 측정 금융자산 | B11: 453413 | C11: 0
A12: 외화부채 | B12: 외화부채 | C12: 외화부채
A13: 매입채무 | B13: -2178932 | C13: 0
A14: 기타지급채무 | B14: -259828 | C14: -263204
A15: 순외화자산(부채) | B15: 639198 | C15: -198090
A17: 당기말과 전기말 현재, 다른 모든 변수가 일정하고 원화가 미국달러화에 대해 10% 약세 또는 강세를 가정할 경우, 당기 세후이익은 14,491천원(전기: 15,629천원), 자본은 49,857천원(전기: 15,629천원)만큼 상승 또는 하락하였을 것입니다.
A18: 당기말과 전기말에 적용된 환율은 다음과 같습니다.
B19: (단위: 원)
A20: 구 분 | B20: 평균환율 | C20: 평균환율 | D20: 기말환율 | E20: 기말환율
A21: 구 분 | B21: 당 기 | C21: 전 기 | D21: 당기말 | E21: 전기말
A22: USD | B22: 1422.22 | C22: 1363.98 | D22: 1434.9 | E22: 1470
A24: 상기 민감도 분석은 당기말과 전기말 현재 외화로 표시된 화폐성 자산 및 부채를 대상으로 하였습니다.
A25: (2) 가격위험
A26: 당사는 재무상태표상 당기손익-공정가치 측정 금융자산과 기타포괄손익-공정가치 측정 금융자산으로 분류되는 당사 보유 지분증권의 가격위험에 노출되어 있습니다.당사가 보유하고 있는 상장주식은 공개시장에서 거래되고 있으며, KOSPI 주가지수 또는 NASDAQ 주가지수 중 하나에 속해 있습니다.
A27: 당사가 보유하고 있는 상장주식 가격의 상승 또는 하락이 당기 및 전기의 세후손익 및 세후자본에 미치는 영향은 아래 표와 같습니다. 이 분석은 다른 변수들은 일정하며 당사가 보유하고 있는 상장주식의 가격이 일정하게 10% 상승 또는 하락하는 경우를 가정하여 세후 효과로 분석한 것입니다.
B28: (단위: 천원)
A29: 지 수 | B29: 지 수 | C29: 당 기 | D29: 당 기 | E29: 전 기 | F29: 전 기
A30: 지 수 | B30: 지 수 | C30: 손 익 | D30: 자 본 | E30: 손 익 | F30: 자 본
A31: 상장주식 | B31: 10% 상승시 | C31: 107823 | D31: 255187 | E31: 0 | F31: 88405
A32: 상장주식 | B32: 10% 하락시 | C32: -107823 | D32: -255187 | E32: 0 | F32: -88405
A34: 한편, 보고기간종료일 현재 당사가 보유하고 있는 당기손익-공정가치 측정 금융자산은 조합출자금, 상장주식 및 해외채권으로서, 조합출자금은 발행기관이 공시한 환매가격을 기초로 공정가치를 측정하고 있으며 상장주식 및 해외채권은 보고기간종료일현재의 시장가격(또는 평가기관이 산정한 공정가치)을 기초로 공정가치를 측정하고 있습니다. 또한 동 당기손익-공정가치 측정 금융자산의 최대 가격위험 노출금액은 해당 자산의 장부금액입니다.(3) 이자율위험보고기간종료일 현재 당사는 차입금을 보유하고 있지 않으므로 이자율위험에 노출되어 있지 않습니다.
A35: 4.1.2 신용 위험신용위험은 기업 및 개인 고객에 대한 신용거래 및 채권 뿐 아니라 현금성자산, 채무상품의 계약 현금흐름, 예치금 등에서도 발생합니다. (1) 위험관리은행 및 금융기관의 경우, 신용등급이 우수한 금융기관과 거래하고 있으므로 금융기관으로부터의 신용위험은 제한적입니다. 당사의 신용위험은 개별 고객, 산업, 지역 등에 대한 유의적인 집중은 없습니다.
A36: 당사가 보유하는 채무상품은 모두 낮은 신용위험의 상품에 해당합니다. 이러한 채무상품들에 대해서는 신용등급을 모니터링하여 신용위험의 하락을 평가하고 있습니다.(2) 금융자산의 손상당사는 기대신용손실 모형이 적용되는 다음의 금융자산을 보유하고 있습니다.
A37: ㆍ 재화 및 용역의 제공에 따른 매출채권ㆍ 용역 제공에 따른 계약자산
A38: ㆍ 상각후원가로 측정하는 기타 금융자산
A39: 현금성자산도 손상 규정의 적용대상에 포함되나 식별된 기대신용손실은 유의적이지 않습니다.
A40: 당사는 매출채권 및 계약자산에 대해 전체 기간 기대신용손실을 손실충당금으로 인식하는 간편법을 적용합니다. 기대신용손실을 측정하기 위해 매출채권은 신용위험 특성과 연체일을 기준으로 구분하였습니다. 상각후원가로 측정하는 기타 금융자산에는 대여금, 보증금, 미수금 등이 포함됩니다.상각후원가로 측정하는 기타 금융자산은 전체기간 기대신용손실로 손실충당금을 인식한 1년 이상 초과 연체채권을 제외하고 모두 신용위험이 낮은 것으로 판단되며, 따라서 손실충당금은 12개월 기대신용손실로 인식하였습니다.
A41: 당기말과 전기말 현재 매출채권에 대한 기대신용손실 및 각 연령별로 손상된 금액은 다음과 같습니다.
B42: (단위: 천원)
A43: 구 분 | B43: 당기말 | C43: 당기말 | D43: 당기말 | E43: 전기말 | F43: 전기말 | G43: 전기말
A44: 구 분 | B44: 기대손실율 | C44: 채권잔액 | D44: 손상된 금액 | E44: 기대손실율 | F44: 채권잔액 | G44: 손상된 금액
...

Sheet 5
A1: 5. 금융상품 공정가치 | J1: =HYPERLINK("#총괄표!A1","◀ 총괄표")
A3: 5.1 금융상품 종류별 공정가치당기 중 당사의 금융자산과 금융부채의 공정가치에 영향을 미치는 사업환경 및 경제적인 환경의 유의적인 변동은 없습니다. 따라서 상각후원가로 측정하는 당사의 금융자산과 금융부채의 장부금액은 공정가치의 합리적 근사치이므로 공정가치를 공시하지 않았습니다.
A4: 5.2 공정가치 서열체계
A5: 공정가치로 측정되는 금융상품은 공정가치 서열체계에 따라 구분되며 정의된 수준들은 다음과 같습니다.
A6: - | B6: 측정일에 동일한 자산이나 부채에 대해 접근할 수 있는 활성시장의 (조정하지 않은) 공시가격 (수준 1)
A7: - | B7: 수준 1의 공시가격 외에 자산이나 부채에 대해 직접적으로나 간접적으로 관측할 수 있는투입변수 (수준 2)
A8: - | B8: 자산이나 부채에 대한 관측할 수 없는 투입변수 (수준 3)
A10: 당기말과 전기말 현재 반복적으로 공정가치로 측정되고 인식된 당사의 금융자산은 다음과 같습니다.
A11: <당기말>
B12: (단위: 천원)
A13: 구 분 | B13: 수준1 | C13: 수준2 | D13: 수준3 | E13: 합 계
A14: 반복적인 공정가치 측정치 | B14: 반복적인 공정가치 측정치 | C14: 반복적인 공정가치 측정치 | D14: 반복적인 공정가치 측정치 | E14: 반복적인 공정가치 측정치
A15: 당기손익-공정가치 측정 금융자산 | B15: 1855021 | C15: 0 | D15: 307573 | E15: 2162594
A16: 기타포괄손익-공정가치 측정 금융자산 | B16: 1863009 | C16: 0 | D16: 0 | E16: 1863009
A18: <전기말>
B19: (단위: 천원)
A20: 구 분 | B20: 수준1 | C20: 수준2 | D20: 수준3 | E20: 합 계
A21: 반복적인 공정가치 측정치 | B21: 반복적인 공정가치 측정치 | C21: 반복적인 공정가치 측정치 | D21: 반복적인 공정가치 측정치 | E21: 반복적인 공정가치 측정치
A22: 당기손익-공정가치 측정 금융자산 | B22: 0 | C22: 1005940 | D22: 297963 | E22: 1303903
A23: 기타포괄손익-공정가치 측정 금융자산 | B23: 1117640 | C23: 0 | D23: 0 | E23: 1117640
A25: 5.3 반복적인 공정가치 측정치의 서열체계 수준 간 이동
A26: 당기 중 수준 1과 수준 2간의 유의적인 이동은 없으며, 당기 및 전기 중 수준 3으로 분류된 금융상품의 변동 내역은 다음과 같습니다.
B27: (단위: 천원)
A28: 구 분 | B28: 당기손익-공정가치 측정 금융자산 | C28: 당기손익-공정가치 측정 금융자산
A29: 구 분 | B29: 당 기 | C29: 전 기
A30: 기초 | B30: 297963 | C30: 0
A31: 수준 2로부터의 이동 | B31: 0 | C31: 290163
A32: 평가 | B32: 9610 | C32: 7800
A33: 기말 | B33: 307573 | C33: 297963
A34: └ 푸팅검증: 기말(행 33) − Σ(행) | B34: =IF(ABS(B33-(SUM(B30:B32)))<1.5,TRUE,B33-(SUM(B30:B32))) | C34: =IF(ABS(C33-(SUM(C30:C32)))<1.5,TRUE,C33-(SUM(C30:C32)))
A36: 5.4 가치평가기법 및 투입변수보고기간종료일 현재 당사는 공정가치 서열체계에서 수준3으로 분류되는 반복적인 공정가치측정치, 비반복적인 공정가치측청치에 대해 다음의 가치평가기법과 투입변수를 사용하고 있습니다.
B37: (단위: 천원)
A38: 구분 | B38: 공정가치 | C38: 수준 | D38: 가치평가법 | E38: 투입변수
A39: 당기손익-공정가치 측정 금융자산 | B39: 당기손익-공정가치 측정 금융자산 | C39: 당기손익-공정가치 측정 금융자산 | D39: 당기손익-공정가치 측정 금융자산 | E39: 당기손익-공정가치 측정 금융자산
A40: 출자금 | B40: 307573 | C40: 3 | D40: 순자산가치법 | E40: 순자산가치

Sheet 6
A1: 6. 범주별 금융상품 | J1: =HYPERLINK("#총괄표!A1","◀ 총괄표")
A3: 6.1 금융상품 범주별 장부금액
A4: 당기말과 전기말 현재 범주별 금융상품의 장부금액은 다음과 같습니다.<당기말>
B5: (단위: 천원)
A6: 구 분 | B6: 상각후원가 측정금융자산 | C6: 당기손익-공정가치측정 금융자산 | D6: 기타포괄손익-공정가치측정 금융자산 | E6: 상각후원가 측정금융부채
A7: 현금및현금성자산 | B7: 4026180 | C7: 0 | D7: 0 | E7: 0
A8: 매출채권및기타채권 | B8: 8034792 | C8: 0 | D8: 0 | E8: 0
A9: 당기손익-공정가치 측정 금융자산 | B9: 0 | C9: 2162594 | D9: 0 | E9: 0
A10: 기타포괄손익-공정가치 측정 금융자산 | B10: 0 | C10: 0 | D10: 1863009 | E10: 0
A11: 매입채무및기타지급채무(*) | B11: 0 | C11: 0 | D11: 0 | E11: -5739452
A12: 합 계 | B12: 12060972 | C12: 2162594 | D12: 1863009 | E12: -5739452
A13: └ 푸팅검증: 합 계(행 12) − Σ(행) | B13: =IF(ABS(B12-(SUM(B7:B11)))<1.5,TRUE,B12-(SUM(B7:B11))) | C13: =IF(ABS(C12-(SUM(C7:C11)))<1.5,TRUE,C12-(SUM(C7:C11))) | D13: =IF(ABS(D12-(SUM(D7:D11)))<1.5,TRUE,D12-(SUM(D7:D11))) | E13: =IF(ABS(E12-(SUM(E7:E11)))<1.5,TRUE,E12-(SUM(E7:E11)))
A15: <전기말>
B16: (단위: 천원)
A17: 구 분 | B17: 상각후원가 측정금융자산 | C17: 당기손익-공정가치측정 금융자산 | D17: 기타포괄손익-공정가치측정 금융자산 | E17: 상각후원가측정금융부채
A18: 현금및현금성자산 | B18: 7065892 | C18: 0 | D18: 0 | E18: 0
A19: 매출채권및기타채권 | B19: 3788663 | C19: 0 | D19: 0 | E19: 0
A20: 당기손익-공정가치 측정 금융자산 | B20: 0 | C20: 1303903 | D20: 0 | E20: 0
A21: 기타포괄손익-공정가치 측정 금융자산 | B21: 0 | C21: 0 | D21: 1117640 | E21: 0
A22: 매입채무및기타지급채무(*) | B22: 0 | C22: 0 | D22: 0 | E22: -3465922
A23: 합 계 | B23: 10854555 | C23: 1303903 | D23: 1117640 | E23: -3465922
A24: └ 푸팅검증: 합 계(행 23) − Σ(행) | B24: =IF(ABS(B23-(SUM(B18:B22)))<1.5,TRUE,B23-(SUM(B18:B22))) | C24: =IF(ABS(C23-(SUM(C18:C22)))<1.5,TRUE,C23-(SUM(C18:C22))) | D24: =IF(ABS(D23-(SUM(D18:D22)))<1.5,TRUE,D23-(SUM(D18:D22))) | E24: =IF(ABS(E23-(SUM(E18:E22)))<1.5,TRUE,E23-(SUM(E18:E22)))
A26: (*) 기타지급채무 중 종업원급여제도에 따른 당사의 의무에 대응하는 종업원급여부채 262,318천원(전기말: 270,527천원)은 금융상품 공시 대상이 아니므로 제외되었습니다. 또한, 리스이용자로서 리스계약에 따른 리스부채는 포함하지 않았습니다.
A27: 6.2 금융상품 범주별 순손익
A28: 당기와 전기 중 금융상품 범주별 순손익은 다음과 같습니다.
B29: (단위: 천원)
A30: 구 분 | B30: 당 기 | C30: 전 기
A31: 상각후원가 측정 금융자산 | B31: 상각후원가 측정 금융자산 | C31: 상각후원가 측정 금융자산
A32: 이자수익 | B32: 112719 | C32: 229416
A33: 대손상각비 | B33: -9851 | C33: -158549
A34: 외환차손익 | B34: -24946 | C34: -15854
A35: 외화평가손익 | B35: 46891 | C35: -8027
A36: 당기손익-공정가치 측정 금융자산 | B36: 당기손익-공정가치 측정 금융자산 | C36: 당기손익-공정가치 측정 금융자산
A37: 평가및처분손익 | B37: 501439 | C37: 13740
A38: 배당금수익 | B38: 864 | C38: 0
A39: 기타포괄손익-공정가치 측정 금융자산 | B39: 기타포괄손익-공정가치 측정 금융자산 | C39: 기타포괄손익-공정가치 측정 금융자산
A40: 배당금수익 | B40: 69828 | C40: 30421
A41: 평가손익(기타포괄손익) | B41: 419571 | C41: -397060
A42: 상각후원가 측정 금융부채 | B42: 상각후원가 측정 금융부채 | C42: 상각후원가 측정 금융부채
A43: 이자비용 | B43: 0 | C43: -49998
...

Sheet 7
A1: 7. 영업부문 | J1: =HYPERLINK("#총괄표!A1","◀ 총괄표")
A3: (1) 보고부문에 대한 정보당사의 영업부문은 수익을 창출하고 비용을 발생시키는 사업활동을 영위하는 식별가능한 구성단위로서 부문의 성과평가를 위하여 최고의사결정자가 주기적으로 검토하는 내부보고자료에 기초하여 부문을 구분하고 있습니다. 경영진은 당사의 경제적 특성이 유사한 영업부문을 통합하여 보고부문을 구성하고 있습니다.보고기간 종료일 현재 당사의 보고부문별 내용은 다음과 같습니다.
A4: 보고부문 | B4: 주요내용
A5: 비즈니스 금융 솔루션 상품 | B5: NSK 서버, OGG 서버, DBMS 솔루션, HSM 보안장비, IOT, 기타 솔루션
A6: 용 역 | B6: 유지보수용역, 개발용역
A7: 기 타 | B7: 펜션 임대 및 관리용역 등
A9: (2) 당기 및 전기 중 부문별 수익 및 매출총이익은 다음과 같습니다.
B10: (단위: 천원)
A11: 구 분 | B11: 당 기 | C11: 당 기 | D11: 당 기 | E11: 당 기 | F11: 전 기 | G11: 전 기 | H11: 전 기 | I11: 전 기
A12: 구 분 | B12: 금융솔루션 | C12: 용 역 | D12: 기 타 | E12: 합 계 | F12: 금융솔루션 | G12: 용 역 | H12: 기 타 | I12: 합 계
A13: 총부문수익 | B13: 9997623 | C13: 14720165 | D13: 145694 | E13: 24863482 | F13: 13595193 | G13: 15775567 | H13: 168595 | I13: 29539355
A14: 매출총이익 | B14: 1826878 | C14: 3384821 | D14: -22938 | E14: 5188761 | F14: 1533717 | G14: 3590022 | H14: -144943 | I14: 4978796
A16: (3) 당사는 보고부문별 자산과 부채에 대하여 최고의사결정권자에게 보고하지 않습니다.(4) 당기와 전기의 매출은 모두 국내(대한민국) 매출이며, 비유동자산은 모두 국내에 소재합니다.(5) 주요 고객에 대한 정보당사의 매출액의 10% 이상을 차지하는 외부 고객의 경우 당기는 B사로서 발생한 매출액은 3,881,251천원이며, 전기는 A사로서 발생한 매출액은 2,979,713천원입니다.

Sheet 8
A1: 8. 현금및현금성자산 | J1: =HYPERLINK("#총괄표!A1","◀ 총괄표")
A3: 당기말과 전기말 현재 현금및현금성자산 내역은 다음과 같습니다.
B4: (단위: 천원)
A5: 구 분 | B5: 당기말 | C5: 전기말
A6: 현금 | B6: 950 | C6: 225
A7: 예적금 등 | B7: 4025230 | C7: 7065667
A8: 합 계 | B8: 4026180 | C8: 7065892
A9: └ 푸팅검증: 합 계(행 8) − Σ(행) | B9: =IF(ABS(B8-(SUM(B6:B7)))<1.5,TRUE,B8-(SUM(B6:B7))) | C9: =IF(ABS(C8-(SUM(C6:C7)))<1.5,TRUE,C8-(SUM(C6:C7)))
A12: ■ 크로스 참조
A13: 주8 현금및현금성자산 합계 = BS 현금및현금성자산 | B13: =IF(ABS(B8*1000-'BS'!B8)<5000,TRUE,B8*1000-'BS'!B8) | C13: → BS!B8

Sheet 9
A1: 9. 매출채권, 계약자산 및 기타 상각후원가 측정 금융자산 | J1: =HYPERLINK("#총괄표!A1","◀ 총괄표")
A3: 당기말과 전기말 현재 매출채권, 계약자산 및 기타 상각후원가 측정 금융자산의 내역은 다음과 같습니다.
B4: (단위: 천원)
A5: 구 분 | B5: 당기말 | C5: 당기말 | D5: 당기말 | E5: 전기말 | F5: 전기말 | G5: 전기말
A6: 구 분 | B6: 총장부금액 | C6: 대손충당금 | D6: 순장부금액 | E6: 총장부금액 | F6: 대손충당금 | G6: 순장부금액
A7: 유동 | B7: 유동 | C7: 유동 | D7: 유동 | E7: 유동 | F7: 유동 | G7: 유동
A8: 매출채권(*) | B8: 7047622 | C8: -353563 | D8: 6694059 | E8: 3114086 | F8: -343712 | G8: 2770374
A9: 기타채권
A10: 단기대여금 | B10: 30690 | C10: 0 | D10: 30690 | E10: 36917 | F10: 0 | G10: 36917
A11: 미수금 | B11: 199644 | C11: -199567 | D11: 77 | E11: 199591 | F11: -199567 | G11: 24
A12: 미수수익 | B12: 0 | C12: 0 | D12: 0 | E12: 46632 | F12: 0 | G12: 46632
A13: 보증금 | B13: 1265216 | C13: 0 | D13: 1265216 | E13: 300000 | F13: 0 | G13: 300000
A14: 소 계 | B14: 1495550 | C14: -199567 | D14: 1295983 | E14: 583140 | F14: -199567 | G14: 383573
A15: 유동 합계 | B15: 8543172 | C15: -553130 | D15: 7990042 | E15: 3697226 | F15: -543279 | G15: 3153947
A16: 비유동 | B16: 비유동 | C16: 비유동 | D16: 비유동 | E16: 비유동 | F16: 비유동 | G16: 비유동
A17: 장기대여금 | B17: 44250 | C17: 0 | D17: 44250 | E17: 49000 | F17: 0 | G17: 49000
A18: 보증금 | B18: 500 | C18: 0 | D18: 500 | E18: 585716 | F18: 0 | G18: 585716
A19: 비유동 합계 | B19: 44750 | C19: 0 | D19: 44750 | E19: 634716 | F19: 0 | G19: 634716
A20: 합 계 | B20: 8587922 | C20: -553130 | D20: 8034792 | E20: 4331942 | F20: -543279 | G20: 3788663
A21: └ 푸팅검증: 소 계(행 14) − 그룹합 | B21: =IF(ABS(B14-(SUM(B10:B13)))<1.5,TRUE,B14-(SUM(B10:B13))) | C21: =IF(ABS(C14-(SUM(C10:C13)))<1.5,TRUE,C14-(SUM(C10:C13))) | D21: =IF(ABS(D14-(SUM(D10:D13)))<1.5,TRUE,D14-(SUM(D10:D13))) | E21: =IF(ABS(E14-(SUM(E10:E13)))<1.5,TRUE,E14-(SUM(E10:E13))) | F21: =IF(ABS(F14-(SUM(F10:F13)))<1.5,TRUE,F14-(SUM(F10:F13))) | G21: =IF(ABS(G14-(SUM(G10:G13)))<1.5,TRUE,G14-(SUM(G10:G13)))
A22: └ 푸팅검증: 합 계(행 20) − 그룹합 | B22: =IF(ABS(B20-(B15+B19))<1.5,TRUE,B20-(B15+B19)) | C22: =IF(ABS(C20-(C15+C19))<1.5,TRUE,C20-(C15+C19)) | D22: =IF(ABS(D20-(D15+D19))<1.5,TRUE,D20-(D15+D19)) | E22: =IF(ABS(E20-(E15+E19))<1.5,TRUE,E20-(E15+E19)) | F22: =IF(ABS(F20-(F15+F19))<1.5,TRUE,F20-(F15+F19)) | G22: =IF(ABS(G20-(G15+G19))<1.5,TRUE,G20-(G15+G19))
A24: (*) 당기말 현재 매출채권에는 계약자산 644,343천원(전기말: 657,455천원)이 포함되어 있습니다.
A25: 매출채권은 정상적인 영업 과정에서 판매된 재화나 용역에 대하여 고객이 지불해야 할 금액입니다. 최초 인식시점에 매출채권이 유의적인 금융요소를 포함하지 않는 경우에는 거래가격을 공정가치로 측정합니다. 당사는 계약상 현금 흐름을 회수하는 목적으로 매출채권을 보유하고 있으므로 상각후원가로 측정하고 있습니다. 당사의 손상 정책 및 손실충당금 계산에 대한 사항은 주석 4.1.2에서 제공됩니다.
A27: ■ 크로스 참조
A28: 주9 매출채권 순장부금액 = BS 매출채권 | B28: =IF(ABS(D8*1000-'BS'!B9)<5000,TRUE,D8*1000-'BS'!B9) | C28: → BS!B9
A29: 주9 기타채권 소계 순장부금액 = BS 기타채권 | B29: =IF(ABS(D14*1000-'BS'!B10)<5000,TRUE,D14*1000-'BS'!B10) | C29: → BS!B10

Sheet 10
A1: 10. 기타자산 | J1: =HYPERLINK("#총괄표!A1","◀ 총괄표")
A3: 당기말과 전기말 현재 기타자산의 내역은 다음과 같습니다.
B4: (단위: 천원)
A5: 구 분 | B5: 당기말 | C5: 당기말 | D5: 전기말 | E5: 전기말
A6: 구 분 | B6: 유 동 | C6: 비유동 | D6: 유 동 | E6: 비유동
A7: 선급금 | B7: 1859036 | C7: 1440167 | D7: 1345711 | E7: 609977
A8: 부가세대급금 | B8: 1708 | C8: 0 | D8: 0 | E8: 0
A9: 합 계 | B9: 1860744 | C9: 1440167 | D9: 1345711 | E9: 609977
A10: └ 푸팅검증: 합 계(행 9) − Σ(행) | B10: =IF(ABS(B9-(SUM(B7:B8)))<1.5,TRUE,B9-(SUM(B7:B8))) | C10: =IF(ABS(C9-(SUM(C7:C8)))<1.5,TRUE,C9-(SUM(C7:C8))) | D10: =IF(ABS(D9-(SUM(D7:D8)))<1.5,TRUE,D9-(SUM(D7:D8))) | E10: =IF(ABS(E9-(SUM(E7:E8)))<1.5,TRUE,E9-(SUM(E7:E8)))
A13: ■ 크로스 참조
A14: 주10 기타자산 합계(유동) = BS 기타유동자산 | B14: =IF(ABS(B9*1000-'BS'!B11)<5000,TRUE,B9*1000-'BS'!B11) | C14: → BS!B11
A15: 주10 기타자산 합계(비유동) = BS 기타비유동자산 | B15: =IF(ABS(C9*1000-'BS'!B22)<5000,TRUE,C9*1000-'BS'!B22) | C15: → BS!B22

Sheet 11
A1: 11. 재고자산 | J1: =HYPERLINK("#총괄표!A1","◀ 총괄표")
A3: 당기말과 전기말 현재 재고자산의 장부금액은 다음과 같습니다.
B4: (단위: 천원)
A5: 구 분 | B5: 당기말 | C5: 당기말 | D5: 당기말 | E5: 전기말 | F5: 전기말 | G5: 전기말
A6: 구 분 | B6: 취득원가 | C6: 평가충당금(*) | D6: 장부금액 | E6: 취득원가 | F6: 평가충당금(*) | G6: 장부금액
A7: 상 품 | B7: 975851 | C7: -686803 | D7: 289048 | E7: 850553 | F7: -361785 | G7: 488768
A9: (*) 당기 중 재고자산의 순실현가능가치에 따른 재고자산평가손실 325,018천원(전기: 361,785천원)을 인식하였으며, 손익계산서의 매출원가에 포함됐습니다.당기와 전기 중 매출원가로 인식된 재고자산의 원가는 각각 8,170,745천원 및 12,061,640천원입니다.
A11: ■ 크로스 참조
A12: 주11 재고자산 장부금액 = BS 재고자산 | B12: =IF(ABS(D7*1000-'BS'!B12)<5000,TRUE,D7*1000-'BS'!B12) | C12: → BS!B12

Sheet 12
A1: 12. 공정가치 측정 금융자산 | J1: =HYPERLINK("#총괄표!A1","◀ 총괄표")
A3: (1) 당기말과 전기말 현재 당기손익-공정가치 측정 금융자산 및 기타포괄손익-공정가치 측정 금융자산의 내역은 다음과 같습니다.
B4: (단위: 천원)
A5: 구 분 | B5: 범 주 | C5: 당기말 | D5: 당기말 | E5: 전기말 | F5: 전기말
A6: 구 분 | B6: 범 주 | C6: 유 동 | D6: 비유동 | E6: 유 동 | F6: 비유동
A7: 지분증권(*1)(*2) | B7: 기타포괄손익-공정가치 측정 금융자산 | C7: 0 | D7: 1863009 | E7: 0 | F7: 1117640
A8: 지분증권, 출자금 외(*3) | B8: 당기손익-공정가치 측정 금융자산 | C8: 1363118 | D8: 799476 | E8: 1005940 | F8: 297963
A9: 합 계 | B9: 합 계 | C9: 1363118 | D9: 2662485 | E9: 1005940 | F9: 1415603
A10: └ 푸팅검증: 합 계(행 9) − Σ(행) | C10: =IF(ABS(C9-(SUM(C7:C8)))<1.5,TRUE,C9-(SUM(C7:C8))) | D10: =IF(ABS(D9-(SUM(D7:D8)))<1.5,TRUE,D9-(SUM(D7:D8))) | E10: =IF(ABS(E9-(SUM(E7:E8)))<1.5,TRUE,E9-(SUM(E7:E8))) | F10: =IF(ABS(F9-(SUM(F7:F8)))<1.5,TRUE,F9-(SUM(F7:F8)))
A12: (*1) 위 지분상품의 처분시에는 관련 기타포괄손익누계액은 이익잉여금으로 재분류되며 당기손익으로 재분류되지 않습니다.(*2) 전기 중 일부 지분상품을 유동자산에서 비유동자산으로 재분류하였습니다.(*3) 동 출자금 중 일부는 거래이행 보증을 위해 소프트웨어공제조합에 담보로 제공되어 있습니다(주석 33 참조).
A13: (2) 당기와 전기 중 기타포괄손익-공정가치 측정 금융자산의 변동내역은 다음과 같습니다.
B14: (단위: 천원)
A15: 구 분 | B15: 당 기 | C15: 전 기
A16: 기초금액 | B16: 1117640 | C16: 3531014
A17: 취 득 | B17: 924798 | C17: 761237
A18: 평가손익 | B18: 419571 | C18: -397060
A19: 처 분 | B19: -599000 | C19: -2777551
A20: 기말금액 | B20: 1863009 | C20: 1117640
A21: └ 푸팅검증: 기말금액(행 20) − Σ(행) | B21: =IF(ABS(B20-(SUM(B16:B19)))<1.5,TRUE,B20-(SUM(B16:B19))) | C21: =IF(ABS(C20-(SUM(C16:C19)))<1.5,TRUE,C20-(SUM(C16:C19)))
A23: (3) 당기와 전기 중 기타포괄손익-공정가치 측정 금융자산의 평가손익 변동내역은 다음과 같습니다.
B24: (단위: 천원)
A25: 구 분 | B25: 당 기 | C25: 전 기
A26: 기초금액 | B26: -1101843 | C26: -763803
A27: 평가금액(법인세효과 반영 전) | B27: 419571 | C27: -397060
A28: 법인세효과 | B28: -76457 | C28: 82986
A29: 처분에 따른 이익잉여금 대체 | B29: -37804 | C29: -23966
A30: 기말금액 | B30: -796533 | C30: -1101843
A31: └ 푸팅검증: 기말금액(행 30) − Σ(행) | B31: =IF(ABS(B30-(SUM(B26:B29)))<1.5,TRUE,B30-(SUM(B26:B29))) | C31: =IF(ABS(C30-(SUM(C26:C29)))<1.5,TRUE,C30-(SUM(C26:C29)))
A33: (4) 당기와 전기 중 당기손익-공정가치 측정 금융자산과 관련하여 손익으로 인식된 금액은 다음과 같습니다.
B34: (단위: 천원)
A35: 구 분 | B35: 당 기 | C35: 전 기
A36: 당기손익-공정가치 측정 금융자산 평가손익 | B36: -83866 | C36: 13740
A37: 당기손익-공정가치 측정 금융자산 처분손익 | B37: 585305 | C37: 0
A38: 합 계 | B38: 501439 | C38: 13740
A39: └ 푸팅검증: 합 계(행 38) − Σ(행) | B39: =IF(ABS(B38-(SUM(B36:B37)))<1.5,TRUE,B38-(SUM(B36:B37))) | C39: =IF(ABS(C38-(SUM(C36:C37)))<1.5,TRUE,C38-(SUM(C36:C37)))

Sheet 13
A1: 13. 유형자산 | J1: =HYPERLINK("#총괄표!A1","◀ 총괄표")
A3: (1) 당기말과 전기말 현재 유형자산 장부금액의 구성내역은 다음과 같습니다.
A4: <당기말>
B5: (단위: 천원)
A6: 구 분 | B6: 토 지 | C6: 건 물 | D6: 차량운반구 | E6: 집기비품 | F6: 기계장치 | G6: 사용권자산 | H6: 구축물 | I6: 합 계
A7: 취득원가 | B7: 5232621 | C7: 1722996 | D7: 15573 | E7: 672746 | F7: 595613 | G7: 382522 | H7: 87563 | I7: 8709634
A8: 감가상각누계액 | B8: 0 | C8: -368901 | D8: -15572 | E8: -649872 | F8: -464002 | G8: -266533 | H8: -87560 | I8: -1852440
A9: 장부금액 | B9: 5232621 | C9: 1354095 | D9: 1 | E9: 22874 | F9: 131611 | G9: 115989 | H9: 3 | I9: 6857194
A10: └ 푸팅검증: 장부금액(행 9) − Σ(행) | B10: =IF(ABS(B9-(SUM(B7:B8)))<1.5,TRUE,B9-(SUM(B7:B8))) | C10: =IF(ABS(C9-(SUM(C7:C8)))<1.5,TRUE,C9-(SUM(C7:C8))) | D10: =IF(ABS(D9-(SUM(D7:D8)))<1.5,TRUE,D9-(SUM(D7:D8))) | E10: =IF(ABS(E9-(SUM(E7:E8)))<1.5,TRUE,E9-(SUM(E7:E8))) | F10: =IF(ABS(F9-(SUM(F7:F8)))<1.5,TRUE,F9-(SUM(F7:F8))) | G10: =IF(ABS(G9-(SUM(G7:G8)))<1.5,TRUE,G9-(SUM(G7:G8))) | H10: =IF(ABS(H9-(SUM(H7:H8)))<1.5,TRUE,H9-(SUM(H7:H8))) | I10: =IF(ABS(I9-(SUM(I7:I8)))<1.5,TRUE,I9-(SUM(I7:I8)))
A12: <전기말>
B13: (단위: 천원)
A14: 구 분 | B14: 토 지 | C14: 건 물 | D14: 차량운반구 | E14: 집기비품 | F14: 기계장치 | G14: 사용권자산 | H14: 구축물 | I14: 합 계
A15: 취득원가 | B15: 5232621 | C15: 1722996 | D15: 31250 | E15: 661061 | F15: 515238 | G15: 382522 | H15: 87563 | I15: 8633251
A16: 감가상각누계액 | B16: 0 | C16: -325826 | D16: -25370 | E16: -623214 | F16: -419551 | G16: -89094 | H16: -77903 | I16: -1560958
A17: 장부금액 | B17: 5232621 | C17: 1397170 | D17: 5880 | E17: 37847 | F17: 95687 | G17: 293428 | H17: 9660 | I17: 7072293
A18: └ 푸팅검증: 장부금액(행 17) − Σ(행) | B18: =IF(ABS(B17-(SUM(B15:B16)))<1.5,TRUE,B17-(SUM(B15:B16))) | C18: =IF(ABS(C17-(SUM(C15:C16)))<1.5,TRUE,C17-(SUM(C15:C16))) | D18: =IF(ABS(D17-(SUM(D15:D16)))<1.5,TRUE,D17-(SUM(D15:D16))) | E18: =IF(ABS(E17-(SUM(E15:E16)))<1.5,TRUE,E17-(SUM(E15:E16))) | F18: =IF(ABS(F17-(SUM(F15:F16)))<1.5,TRUE,F17-(SUM(F15:F16))) | G18: =IF(ABS(G17-(SUM(G15:G16)))<1.5,TRUE,G17-(SUM(G15:G16))) | H18: =IF(ABS(H17-(SUM(H15:H16)))<1.5,TRUE,H17-(SUM(H15:H16))) | I18: =IF(ABS(I17-(SUM(I15:I16)))<1.5,TRUE,I17-(SUM(I15:I16)))
A20: (2) 당기와 전기 중 유형자산 장부금액의 변동내역은 다음과 같습니다.<당기>
B21: (단위: 천원)
A22: 구 분 | B22: 토 지 | C22: 건 물 | D22: 차량운반구 | E22: 집기비품 | F22: 기계장치 | G22: 사용권자산 | H22: 구축물 | I22: 합 계
A23: 기초금액 | B23: 5232621 | C23: 1397170 | D23: 5880 | E23: 37847 | F23: 95687 | G23: 293428 | H23: 9660 | I23: 7072293
A24: 취득 | B24: 0 | C24: 0 | D24: 0 | E24: 11685 | F24: 84926 | G24: 0 | H24: 0 | I24: 96611
A25: 처분 | B25: 0 | C25: 0 | D25: -5226 | E25: 0 | F25: -1 | G25: 0 | H25: 0 | I25: -5227
A26: 감가상각 | B26: 0 | C26: -43075 | D26: -653 | E26: -26658 | F26: -49001 | G26: -177439 | H26: -9657 | I26: -306483
A27: 기말금액 | B27: 5232621 | C27: 1354095 | D27: 1 | E27: 22874 | F27: 131611 | G27: 115989 | H27: 3 | I27: 6857194
A28: └ 푸팅검증: 기말금액(행 27) − Σ(행) | B28: =IF(ABS(B27-(SUM(B23:B26)))<1.5,TRUE,B27-(SUM(B23:B26))) | C28: =IF(ABS(C27-(SUM(C23:C26)))<1.5,TRUE,C27-(SUM(C23:C26))) | D28: =IF(ABS(D27-(SUM(D23:D26)))<1.5,TRUE,D27-(SUM(D23:D26))) | E28: =IF(ABS(E27-(SUM(E23:E26)))<1.5,TRUE,E27-(SUM(E23:E26))) | F28: =IF(ABS(F27-(SUM(F23:F26)))<1.5,TRUE,F27-(SUM(F23:F26))) | G28: =IF(ABS(G27-(SUM(G23:G26)))<1.5,TRUE,G27-(SUM(G23:G26))) | H28: =IF(ABS(H27-(SUM(H23:H26)))<1.5,TRUE,H27-(SUM(H23:H26))) | I28: =IF(ABS(I27-(SUM(I23:I26)))<1.5,TRUE,I27-(SUM(I23:I26)))
A30: <전기>
B31: (단위: 천원)
A32: 구 분 | B32: 토 지 | C32: 건 물 | D32: 차량운반구 | E32: 집기비품 | F32: 기계장치 | G32: 사용권자산 | H32: 구축물 | I32: 합 계
A33: 기초금액 | B33: 5232007 | C33: 1325931 | D33: 9799 | E33: 55229 | F33: 78292 | G33: 142488 | H33: 27173 | I33: 6870919
A34: 취득 | B34: 614 | C34: 113076 | D34: 0 | E34: 10277 | F34: 71240 | G34: 327235 | H34: 0 | I34: 522442
A35: 감가상각 | B35: 0 | C35: -41837 | D35: -3919 | E35: -27659 | F35: -53845 | G35: -176295 | H35: -17513 | I35: -321068
A36: 기말금액 | B36: 5232621 | C36: 1397170 | D36: 5880 | E36: 37847 | F36: 95687 | G36: 293428 | H36: 9660 | I36: 7072293
A37: └ 푸팅검증: 기말금액(행 36) − Σ(행) | B37: =IF(ABS(B36-(SUM(B33:B35)))<1.5,TRUE,B36-(SUM(B33:B35))) | C37: =IF(ABS(C36-(SUM(C33:C35)))<1.5,TRUE,C36-(SUM(C33:C35))) | D37: =IF(ABS(D36-(SUM(D33:D35)))<1.5,TRUE,D36-(SUM(D33:D35))) | E37: =IF(ABS(E36-(SUM(E33:E35)))<1.5,TRUE,E36-(SUM(E33:E35))) | F37: =IF(ABS(F36-(SUM(F33:F35)))<1.5,TRUE,F36-(SUM(F33:F35))) | G37: =IF(ABS(G36-(SUM(G33:G35)))<1.5,TRUE,G36-(SUM(G33:G35))) | H37: =IF(ABS(H36-(SUM(H33:H35)))<1.5,TRUE,H36-(SUM(H33:H35))) | I37: =IF(ABS(I36-(SUM(I33:I35)))<1.5,TRUE,I36-(SUM(I33:I35)))
A39: (3) 당기와 전기 중 발생한 감가상각비의 배부내역은 다음과 같습니다.
B40: (단위: 천원)
A41: 구 분 | B41: 당 기 | C41: 전 기
A42: 매출원가 | B42: 179780 | C42: 182558
A43: 판매비와관리비 | B43: 126703 | C43: 138510
A44: 합 계 | B44: 306483 | C44: 321068
A45: └ 푸팅검증: 합 계(행 44) − Σ(행) | B45: =IF(ABS(B44-(SUM(B42:B43)))<1.5,TRUE,B44-(SUM(B42:B43))) | C45: =IF(ABS(C44-(SUM(C42:C43)))<1.5,TRUE,C44-(SUM(C42:C43)))
...

Sheet 14
A1: 14. 리스 | J1: =HYPERLINK("#총괄표!A1","◀ 총괄표")
A3: (1) 당기와 전기 중 사용권자산의 변동내역은 다음과 같습니다.<당기>
B4: (단위: 천원)
A5: 구 분 | B5: 당기초 | C5: 증 가 | D5: 감가상각비 | E5: 당기말 | F5: └ 행검증: 당기말 − (당기초 +증가 +감가상각비)
A6: 사용권자산
A7: 부동산 | B7: 272696 | C7: 0 | D7: -163618 | E7: 109078 | F7: =IF(ABS(E7-(B7+C7+D7))<1.5,TRUE,E7-(B7+C7+D7))
A8: 차량운반구 | B8: 20732 | C8: 0 | D8: -13821 | E8: 6911 | F8: =IF(ABS(E8-(B8+C8+D8))<1.5,TRUE,E8-(B8+C8+D8))
A9: 합 계 | B9: 293428 | C9: 0 | D9: -177439 | E9: 115989 | F9: =IF(ABS(E9-(B9+C9+D9))<1.5,TRUE,E9-(B9+C9+D9))
A10: └ 푸팅검증: 합 계(행 9) − Σ(행) | B10: =IF(ABS(B9-(SUM(B7:B8)))<1.5,TRUE,B9-(SUM(B7:B8))) | D10: =IF(ABS(D9-(SUM(D7:D8)))<1.5,TRUE,D9-(SUM(D7:D8))) | E10: =IF(ABS(E9-(SUM(E7:E8)))<1.5,TRUE,E9-(SUM(E7:E8)))
A12: <전기>
B13: (단위: 천원)
A14: 구 분 | B14: 전기초 | C14: 증 가 | D14: 감가상각비 | E14: 전기말 | F14: └ 행검증: 전기말 − (전기초 +증가 +감가상각비)
A15: 사용권자산
A16: 부동산 | B16: 107934 | C16: 327235 | D16: -162473 | E16: 272696 | F16: =IF(ABS(E16-(B16+C16+D16))<1.5,TRUE,E16-(B16+C16+D16))
A17: 차량운반구 | B17: 34554 | C17: 0 | D17: -13822 | E17: 20732 | F17: =IF(ABS(E17-(B17+C17+D17))<1.5,TRUE,E17-(B17+C17+D17))
A18: 합 계 | B18: 142488 | C18: 327235 | D18: -176295 | E18: 293428 | F18: =IF(ABS(E18-(B18+C18+D18))<1.5,TRUE,E18-(B18+C18+D18))
A19: └ 푸팅검증: 합 계(행 18) − Σ(행) | B19: =IF(ABS(B18-(SUM(B16:B17)))<1.5,TRUE,B18-(SUM(B16:B17))) | C19: =IF(ABS(C18-(SUM(C16:C17)))<1.5,TRUE,C18-(SUM(C16:C17))) | D19: =IF(ABS(D18-(SUM(D16:D17)))<1.5,TRUE,D18-(SUM(D16:D17))) | E19: =IF(ABS(E18-(SUM(E16:E17)))<1.5,TRUE,E18-(SUM(E16:E17)))
A21: (2) 당기와 전기 중 리스부채의 변동내역은 다음과 같습니다.<당기>
B22: (단위: 천원)
A23: 구 분 | B23: 당기초 | C23: 증 가 | D23: 상환금액 | E23: 이자비용 | F23: 당기말 | G23: 유 동 | H23: 비유동 | I23: └ 행검증: 당기말 − (당기초 +증가 +상환금액 +이자비용)
A24: 리스부채
A25: 부동산 | B25: 274391 | C25: 0 | D25: -170113 | E25: 7546 | F25: 111824 | G25: 111824 | H25: 0 | I25: =IF(ABS(F25-(B25+C25+D25+E25))<1.5,TRUE,F25-(B25+C25+D25+E25))
A26: 차량운반구 | B26: 21896 | C26: 0 | D26: -15120 | E26: 686 | F26: 7462 | G26: 7462 | H26: 0 | I26: =IF(ABS(F26-(B26+C26+D26+E26))<1.5,TRUE,F26-(B26+C26+D26+E26))
A27: 합 계 | B27: 296287 | C27: 0 | D27: -185233 | E27: 8232 | F27: 119286 | G27: 119286 | H27: 0 | I27: =IF(ABS(F27-(B27+C27+D27+E27))<1.5,TRUE,F27-(B27+C27+D27+E27))
A28: └ 푸팅검증: 합 계(행 27) − Σ(행) | B28: =IF(ABS(B27-(SUM(B25:B26)))<1.5,TRUE,B27-(SUM(B25:B26))) | D28: =IF(ABS(D27-(SUM(D25:D26)))<1.5,TRUE,D27-(SUM(D25:D26))) | E28: =IF(ABS(E27-(SUM(E25:E26)))<1.5,TRUE,E27-(SUM(E25:E26))) | F28: =IF(ABS(F27-(SUM(F25:F26)))<1.5,TRUE,F27-(SUM(F25:F26))) | G28: =IF(ABS(G27-(SUM(G25:G26)))<1.5,TRUE,G27-(SUM(G25:G26)))
A30: <전기>
B31: (단위: 천원)
A32: 구 분 | B32: 전기초 | C32: 증 가 | D32: 상환금액 | E32: 이자비용 | F32: 전기말 | G32: 유 동 | H32: 비유동 | I32: └ 행검증: 전기말 − (전기초 +증가 +상환금액 +이자비용)
A33: 리스부채
A34: 부동산 | B34: 111396 | C34: 327235 | D34: -170113 | E34: 5873 | F34: 274391 | G34: 162567 | H34: 111824 | I34: =IF(ABS(F34-(B34+C34+D34+E34))<1.5,TRUE,F34-(B34+C34+D34+E34))
A35: 차량운반구 | B35: 35701 | C35: 0 | D35: -15120 | E35: 1315 | F35: 21896 | G35: 14434 | H35: 7462 | I35: =IF(ABS(F35-(B35+C35+D35+E35))<1.5,TRUE,F35-(B35+C35+D35+E35))
A36: 합 계 | B36: 147097 | C36: 327235 | D36: -185233 | E36: 7188 | F36: 296287 | G36: 177001 | H36: 119286 | I36: =IF(ABS(F36-(B36+C36+D36+E36))<1.5,TRUE,F36-(B36+C36+D36+E36))
A37: └ 푸팅검증: 합 계(행 36) − Σ(행) | B37: =IF(ABS(B36-(SUM(B34:B35)))<1.5,TRUE,B36-(SUM(B34:B35))) | C37: =IF(ABS(C36-(SUM(C34:C35)))<1.5,TRUE,C36-(SUM(C34:C35))) | D37: =IF(ABS(D36-(SUM(D34:D35)))<1.5,TRUE,D36-(SUM(D34:D35))) | E37: =IF(ABS(E36-(SUM(E34:E35)))<1.5,TRUE,E36-(SUM(E34:E35))) | F37: =IF(ABS(F36-(SUM(F34:F35)))<1.5,TRUE,F36-(SUM(F34:F35))) | G37: =IF(ABS(G36-(SUM(G34:G35)))<1.5,TRUE,G36-(SUM(G34:G35))) | H37: =IF(ABS(H36-(SUM(H34:H35)))<1.5,TRUE,H36-(SUM(H34:H35)))
A39: (3) 당기와 전기 중 리스와 관련하여 손익으로 인식한 금액은 다음과 같습니다.
B40: (단위: 천원)
A41: 구 분 | B41: 당 기 | C41: 전 기
A42: 사용권자산 감가상각비 | B42: 177439 | C42: 176295
A43: 리스부채에 대한 이자비용 | B43: 8232 | C43: 7188
A44: 단기리스에 관한 비용 | B44: 360 | C44: 360
A45: 소액자산 리스에 관한 비용 | B45: 9574 | C45: 13055
...

Sheet 15
A1: 15. 무형자산 | J1: =HYPERLINK("#총괄표!A1","◀ 총괄표")
A3: 당사의 무형자산은 회원권으로 구성되어 있으며, 당기말과 전기말 현재 무형자산의 장부금액의 구성내역은 다음과 같습니다.
B4: (단위: 천원)
A5: 구 분 | B5: 당기말 | C5: 전기말
A6: 취득원가 | B6: 684002 | C6: 684002
A7: 손상차손누계액(*) | B7: -287865 | C7: -287865
A8: 장부금액 | B8: 396137 | C8: 396137
A9: └ 푸팅검증: 장부금액(행 8) − Σ(행) | B9: =IF(ABS(B8-(SUM(B6:B7)))<1.5,TRUE,B8-(SUM(B6:B7))) | C9: =IF(ABS(C8-(SUM(C6:C7)))<1.5,TRUE,C8-(SUM(C6:C7)))
A11: (*) 당사는 전기 중 회원권에 대해 회수가능액을 평가하여 손상차손환입 240,000천원을 영업외수익으로 인식하였습니다.당사는 회원권에 대해서 비한정 내용연수를 가진 무형자산으로 분류하고 매년 손상여부를 검토하고 있습니다.
A13: ■ 크로스 참조
A14: 주15 무형자산 장부금액 = BS 무형자산 | B14: =IF(ABS(B8*1000-'BS'!B21)<5000,TRUE,B8*1000-'BS'!B21) | C14: → BS!B21

Sheet 16
A1: 16. 매입채무 및 기타지급채무 | J1: =HYPERLINK("#총괄표!A1","◀ 총괄표")
A3: 당기말과 전기말 현재 매입채무 및 기타지급채무의 내역은 다음과 같습니다.
B4: (단위: 천원)
A5: 구 분 | B5: 당기말 | C5: 전기말
A6: 매입채무 | B6: 4092019 | C6: 1080657
A7: 기타지급채무
A8: 미지급금 | B8: 1570167 | C8: 2333086
A9: 미지급비용 | B9: 339584 | C9: 322707
A10: 소 계 | B10: 1909751 | C10: 2655793
A11: 합 계 | B11: 6001770 | C11: 3736450
A12: └ 푸팅검증: 소 계(행 10) − 그룹합 | B12: =IF(ABS(B10-(SUM(B8:B9)))<1.5,TRUE,B10-(SUM(B8:B9))) | C12: =IF(ABS(C10-(SUM(C8:C9)))<1.5,TRUE,C10-(SUM(C8:C9)))
A13: └ 푸팅검증: 합 계(행 11) − 그룹합 | B13: =IF(ABS(B11-(B6+B10))<1.5,TRUE,B11-(B6+B10)) | C13: =IF(ABS(C11-(C6+C10))<1.5,TRUE,C11-(C6+C10))
A16: ■ 크로스 참조
A17: 주16 매입채무 = BS 매입채무 | B17: =IF(ABS(B6*1000-'BS'!B26)<5000,TRUE,B6*1000-'BS'!B26) | C17: → BS!B26
A18: 주16 기타지급채무 소계 = BS 기타지급채무 | B18: =IF(ABS(B10*1000-'BS'!B27)<5000,TRUE,B10*1000-'BS'!B27) | C18: → BS!B27

Sheet 17
A1: 17. 기타부채 | J1: =HYPERLINK("#총괄표!A1","◀ 총괄표")
A3: (1) 당기말과 전기말 현재 기타부채의 내역은 다음과 같습니다.
B4: (단위: 천원)
A5: 구 분 | B5: 당기말 | C5: 전기말
A6: 기타유동부채 | B6: 기타유동부채 | C6: 기타유동부채
A7: 선수금 | B7: 846363 | C7: 208983
A8: 예수금 | B8: 47493 | C8: 49721
A9: 부가세예수금 | B9: 0 | C9: 270059
A10: 복구충당부채 | B10: 20000 | C10: 0
A11: 소송충당부채 | B11: 377033 | C11: 0
A12: 소 계 | B12: 1290889 | C12: 528763
A13: 기타비유동부채 | B13: 기타비유동부채 | C13: 기타비유동부채
A14: 복구충당부채 | B14: 0 | C14: 20000
A15: 합 계 | B15: 1290889 | C15: 548763
A16: └ 푸팅검증: 소 계(행 12) − Σ(행) | B16: =IF(ABS(B12-(SUM(B7:B11)))<1.5,TRUE,B12-(SUM(B7:B11))) | C16: =IF(ABS(C12-(SUM(C7:C11)))<1.5,TRUE,C12-(SUM(C7:C11)))
A17: └ 푸팅검증: 합 계(행 15) − 직전 소계 + Σ(행) | B17: =IF(ABS(B15-(B12+SUM(B14:B14)))<1.5,TRUE,B15-(B12+SUM(B14:B14))) | C17: =IF(ABS(C15-(C12+SUM(C14:C14)))<1.5,TRUE,C15-(C12+SUM(C14:C14)))
A19: (2) 당기 중 충당부채에 대한 변동내역은 다음과 같습니다.<당기>
B20: (단위: 천원)
A21: 구 분 | B21: 기 초 | C21: 전 입 | D21: 대 체(*) | E21: 기 말 | F21: └ 행검증: 기말 − (기초 +전입 +대체(*))
A22: 유 동 | B22: 유 동 | C22: 유 동 | D22: 유 동 | E22: 유 동
A23: 복구충당부채 | B23: 0 | C23: 0 | D23: 20000 | E23: 20000 | F23: =IF(ABS(E23-(B23+C23+D23))<1.5,TRUE,E23-(B23+C23+D23))
A24: 소송충당부채 | B24: 0 | C24: 234911 | D24: 142122 | E24: 377033 | F24: =IF(ABS(E24-(B24+C24+D24))<1.5,TRUE,E24-(B24+C24+D24))
A25: 소 계 | B25: 0 | C25: 234911 | D25: 162122 | E25: 397033 | F25: =IF(ABS(E25-(B25+C25+D25))<1.5,TRUE,E25-(B25+C25+D25))
A26: 비유동 | B26: 비유동 | C26: 비유동 | D26: 비유동 | E26: 비유동
A27: 복구충당부채 | B27: 20000 | C27: 0 | D27: -20000 | E27: 0
A28: 합 계 | B28: 20000 | C28: 234911 | D28: 142122 | E28: 397033 | F28: =IF(ABS(E28-(B28+C28+D28))<1.5,TRUE,E28-(B28+C28+D28))
A29: └ 푸팅검증: 소 계(행 25) − Σ(행) | C29: =IF(ABS(C25-(SUM(C23:C24)))<1.5,TRUE,C25-(SUM(C23:C24))) | D29: =IF(ABS(D25-(SUM(D23:D24)))<1.5,TRUE,D25-(SUM(D23:D24))) | E29: =IF(ABS(E25-(SUM(E23:E24)))<1.5,TRUE,E25-(SUM(E23:E24)))
A30: └ 푸팅검증: 합 계(행 28) − 직전 소계 + Σ(행) | B30: =IF(ABS(B28-(B25+SUM(B27:B27)))<1.5,TRUE,B28-(B25+SUM(B27:B27))) | C30: =IF(ABS(C28-(C25+SUM(C27:C27)))<1.5,TRUE,C28-(C25+SUM(C27:C27))) | D30: =IF(ABS(D28-(D25+SUM(D27:D27)))<1.5,TRUE,D28-(D25+SUM(D27:D27))) | E30: =IF(ABS(E28-(E25+SUM(E27:E27)))<1.5,TRUE,E28-(E25+SUM(E27:E27)))
A32: (*) 당기 중 1심 판결이 선고된 소송과 관련하여, 일부 금액을 미지급금에서 소송충당부채로 재분류하였습니다.
A34: ■ 크로스 참조
A35: 주17 기타유동부채 소계 = BS 기타유동부채 | B35: =IF(ABS(B12*1000-'BS'!B29)<5000,TRUE,B12*1000-'BS'!B29) | C35: → BS!B29

Sheet 18
A1: 18. 종업원급여 | J1: =HYPERLINK("#총괄표!A1","◀ 총괄표")
A3: 18.1 확정급여제도(1) 당기말과 전기말 현재 재무상태표에 인식된 순확정급여자산 관련 자산과 부채의 금액은 다음과 같습니다.
B4: (단위: 천원)
A5: 구 분 | B5: 당기말 | C5: 전기말
A6: 확정급여채무 | B6: 2670233 | C6: 2652568
A7: 사외적립자산 공정가치 | B7: -2813142 | C7: -2802005
A8: 합 계(*) | B8: -142909 | C8: -149437
